Workbook

Sheet Enter Answers
A2: Enter the nine answers across each row
A3: One row per respondent. Each question has its own column. Results calculate automatically.
A4: Enter scores as numbers. Q1 and Q9 accept the original written answers. Contact permission is separate in column M.
A6: Questionnaire record | B6: Stage 2 player ID | C6: Record type | D6: Q1 Memorable experience | E6: Q2 Enjoyment 1–5 | F6: Q3 FRA usefulness 1–5 | G6: Q4 Discouragement 1–5 | H6: Q5 Steering confidence 0–10 | I6: Q6 Recovery confidence 0–10 | J6: Q7 Play again | K6: Q8 FRA again | L6: Q9 Reasons | M6: Contact permission | N6: Collection date | O6: Form wording checked | P6: Entry check
A7: S2-Q001 | B7: S2-P024 | C7: =IF(LEN(B7)=0,"Unlinked",IF(COUNTIFS('Stage 2 ID Key'!$A$7:$A$38,B7)<>1,"Invalid ID",IF(COUNTIFS($B$7:$B$15,B7)>1,"Duplicate ID",INDEX('Stage 2 ID Key'!$B$7:$B$38,MATCH(B7,'Stage 2 ID Key'!$A$7:$A$38,0))))) -> Resident | D7: 好玩，有用。知道如何同步。滑雪如何真實畫面就更好。 | E7: 4 | F7: 4 | G7: 2 | H7: 8 | I7: 8 | J7: Yes | K7: Willing | L7: 好想繼續玩，因為，可以繼續鍛鍊，提高自己的防跌倒能力 | M7: Yes | N7: 45894 | O7: Not checked | P7: =IF('Analysis Data'!N7>0,"Correct flagged items",IF('Analysis Data'!M7=0,"Awaiting answers",IF(O7<>"Matches","Check original form wording",IF(OR(C7="Unlinked",C7="Invalid ID",C7="Duplicate ID"),"Check player ID","Ready to review")))) -> Check original form wording
A8: S2-Q002 | B8: S2-P025 | C8: =IF(LEN(B8)=0,"Unlinked",IF(COUNTIFS('Stage 2 ID Key'!$A$7:$A$38,B8)<>1,"Invalid ID",IF(COUNTIFS($B$7:$B$15,B8)>1,"Duplicate ID",INDEX('Stage 2 ID Key'!$B$7:$B$38,MATCH(B8,'Stage 2 ID Key'!$A$7:$A$38,0))))) -> Resident | D8: 好玩，有用。滑雪畫面一般，唔夠吸引。 | E8: 4 | F8: 5 | G8: 3 | H8: 7 | I8: 8 | J8: Yes | K8: Willing | L8: 玩完知道分數比較開心，成績不錯 | M8: Yes | N8: 45896 | O8: Not checked | P8: =IF('Analysis Data'!N8>0,"Correct flagged items",IF('Analysis Data'!M8=0,"Awaiting answers",IF(O8<>"Matches","Check original form wording",IF(OR(C8="Unlinked",C8="Invalid ID",C8="Duplicate ID"),"Check player ID","Ready to review")))) -> Check original form wording
A9: S2-Q003 | B9: S2-P013 | C9: =IF(LEN(B9)=0,"Unlinked",IF(COUNTIFS('Stage 2 ID Key'!$A$7:$A$38,B9)<>1,"Invalid ID",IF(COUNTIFS($B$7:$B$15,B9)>1,"Duplicate ID",INDEX('Stage 2 ID Key'!$B$7:$B$38,MATCH(B9,'Stage 2 ID Key'!$A$7:$A$38,0))))) -> Resident | D9: 好玩，有用。知道如何平衡。 | E9: 4 | F9: 5 | G9: 2 | H9: 7 | I9: 7 | J9: Yes | K9: Willing | L9: 唔錯的遊戲。 用了培訓不錯。 | M9: Yes | N9: 45904 | O9: Not checked | P9: =IF('Analysis Data'!N9>0,"Correct flagged items",IF('Analysis Data'!M9=0,"Awaiting answers",IF(O9<>"Matches","Check original form wording",IF(OR(C9="Unlinked",C9="Invalid ID",C9="Duplicate ID"),"Check player ID","Ready to review")))) -> Check original form wording
A10: S2-Q004 | B10: S2-P005 | C10: =IF(LEN(B10)=0,"Unlinked",IF(COUNTIFS('Stage 2 ID Key'!$A$7:$A$38,B10)<>1,"Invalid ID",IF(COUNTIFS($B$7:$B$15,B10)>1,"Duplicate ID",INDEX('Stage 2 ID Key'!$B$7:$B$38,MATCH(B10,'Stage 2 ID Key'!$A$7:$A$38,0))))) -> Resident | D10: 好玩，有用。知道如何平衡更有效。畫面比較弱。 | E10: 4 | F10: 4 | G10: 2 | H10: 8 | I10: 8 | J10: Yes | K10: Willing | L10: 有用。幾有用？就好難講。感覺不錯。 | M10: Yes | N10: 45904 | O10: Not checked | P10: =IF('Analysis Data'!N10>0,"Correct flagged items",IF('Analysis Data'!M10=0,"Awaiting answers",IF(O10<>"Matches","Check original form wording",IF(OR(C10="Unlinked",C10="Invalid ID",C10="Duplicate ID"),"Check player ID","Ready to review")))) -> Check original form wording
A11: S2-Q005 | B11: S2-P014 | C11: =IF(LEN(B11)=0,"Unlinked",IF(COUNTIFS('Stage 2 ID Key'!$A$7:$A$38,B11)<>1,"Invalid ID",IF(COUNTIFS($B$7:$B$15,B11)>1,"Duplicate ID",INDEX('Stage 2 ID Key'!$B$7:$B$38,MATCH(B11,'Stage 2 ID Key'!$A$7:$A$38,0))))) -> Resident | D11: 好玩，有用。玩左幾次。 | E11: 5 | F11: 5 | G11: 2 | H11: 8 | I11: 8 | J11: Yes | K11: Willing | L11: 有D人唔試，真系唔知點解。幾有用。可以鍛鍊，集中精神 | M11: Yes | N11: 45910 | O11: Not checked | P11: =IF('Analysis Data'!N11>0,"Correct flagged items",IF('Analysis Data'!M11=0,"Awaiting answers",IF(O11<>"Matches","Check original form wording",IF(OR(C11="Unlinked",C11="Invalid ID",C11="Duplicate ID"),"Check player ID","Ready to review")))) -> Check original form wording
A12: S2-Q006 | B12: S2-P004 | C12: =IF(LEN(B12)=0,"Unlinked",IF(COUNTIFS('Stage 2 ID Key'!$A$7:$A$38,B12)<>1,"Invalid ID",IF(COUNTIFS($B$7:$B$15,B12)>1,"Duplicate ID",INDEX('Stage 2 ID Key'!$B$7:$B$38,MATCH(B12,'Stage 2 ID Key'!$A$7:$A$38,0))))) -> Resident | D12: 好玩，有用。好似好容易，其實有挑戰。畫面要改進。 | E12: 5 | F12: 5 | G12: 1 | H12: 8 | I12: 9 | J12: Yes | K12: Willing | L12: 有用。幾有用？就好難講。比以前進步。 | M12: Yes | N12: 45914 | O12: Not checked | P12: =IF('Analysis Data'!N12>0,"Correct flagged items",IF('Analysis Data'!M12=0,"Awaiting answers",IF(O12<>"Matches","Check original form wording",IF(OR(C12="Unlinked",C12="Invalid ID",C12="Duplicate ID"),"Check player ID","Ready to review")))) -> Check original form wording
A13: S2-Q007 | B13: S2-P017 | C13: =IF(LEN(B13)=0,"Unlinked",IF(COUNTIFS('Stage 2 ID Key'!$A$7:$A$38,B13)<>1,"Invalid ID",IF(COUNTIFS($B$7:$B$15,B13)>1,"Duplicate ID",INDEX('Stage 2 ID Key'!$B$7:$B$38,MATCH(B13,'Stage 2 ID Key'!$A$7:$A$38,0))))) -> Resident | D13: 好玩，有用。比以前好玩好多。 | E13: 4 | F13: 4 | G13: 2 | H13: 8 | I13: 8 | J13: Yes | K13: Willing | L13: 想分享一下體驗。可以提高集中注意力。唔知其他人點解唔試 | M13: Yes | N13: 45915 | O13: Not checked | P13: =IF('Analysis Data'!N13>0,"Correct flagged items",IF('Analysis Data'!M13=0,"Awaiting answers",IF(O13<>"Matches","Check original form wording",IF(OR(C13="Unlinked",C13="Invalid ID",C13="Duplicate ID"),"Check player ID","Ready to review")))) -> Check original form wording
A14: S2-Q008 | B14: S2-P030 | C14: =IF(LEN(B14)=0,"Unlinked",IF(COUNTIFS('Stage 2 ID Key'!$A$7:$A$38,B14)<>1,"Invalid ID",IF(COUNTIFS($B$7:$B$15,B14)>1,"Duplicate ID",INDEX('Stage 2 ID Key'!$B$7:$B$38,MATCH(B14,'Stage 2 ID Key'!$A$7:$A$38,0))))) -> Resident | D14: 好玩，好似無特別用處。滑來滑去，玩左幾次。有時間可以再玩，不過畫面就幼稚一些。 | E14: 4 | F14: 5 | G14: 2 | H14: 6 | I14: 6 | J14: Yes | K14: Willing | L14: 好有用。活動力提高。有遊戲好玩好多， | M14: Yes | N14: 45915 | O14: Not checked | P14: =IF('Analysis Data'!N14>0,"Correct flagged items",IF('Analysis Data'!M14=0,"Awaiting answers",IF(O14<>"Matches","Check original form wording",IF(OR(C14="Unlinked",C14="Invalid ID",C14="Duplicate ID"),"Check player ID","Ready to review")))) -> Check original form wording
A15: S2-Q009 | B15: S2-P023 | C15: =IF(LEN(B15)=0,"Unlinked",IF(COUNTIFS('Stage 2 ID Key'!$A$7:$A$38,B15)<>1,"Invalid ID",IF(COUNTIFS($B$7:$B$15,B15)>1,"Duplicate ID",INDEX('Stage 2 ID Key'!$B$7:$B$38,MATCH(B15,'Stage 2 ID Key'!$A$7:$A$38,0))))) -> Resident | D15: 好玩，有用。玩左好多次。有D挑戰。 | E15: 5 | F15: 5 | G15: 1 | H15: 7 | I15: 7 | J15: Yes | K15: Willing | L15: 感覺有D用，無以前咁痛。可以鍛鍊多D | M15: Yes | N15: 45917 | O15: Not checked | P15: =IF('Analysis Data'!N15>0,"Correct flagged items",IF('Analysis Data'!M15=0,"Awaiting answers",IF(O15<>"Matches","Check original form wording",IF(OR(C15="Unlinked",C15="Invalid ID",C15="Duplicate ID"),"Check player ID","Ready to review")))) -> Check original form wording
A19: Only when an answer is absent: record the reason below
A20: Leave the answer cell above empty, then choose the reason under the same question. Leave this grid empty for answered questions.
A22: Questionnaire record | B22: Stage 2 player ID | D22: Q1 Memorable experience | E22: Q2 Enjoyment 1–5 | F22: Q3 FRA usefulness 1–5 | G22: Q4 Discouragement 1–5 | H22: Q5 Steering confidence 0–10 | I22: Q6 Recovery confidence 0–10 | J22: Q7 Play again | K22: Q8 FRA again | L22: Q9 Reasons
A23: S2-Q001 | B23: =IF(LEN(B7)=0,"",B7) -> S2-P024
A24: S2-Q002 | B24: =IF(LEN(B8)=0,"",B8) -> S2-P025
A25: S2-Q003 | B25: =IF(LEN(B9)=0,"",B9) -> S2-P013
A26: S2-Q004 | B26: =IF(LEN(B10)=0,"",B10) -> S2-P005
A27: S2-Q005 | B27: =IF(LEN(B11)=0,"",B11) -> S2-P014
A28: S2-Q006 | B28: =IF(LEN(B12)=0,"",B12) -> S2-P004
A29: S2-Q007 | B29: =IF(LEN(B13)=0,"",B13) -> S2-P017
A30: S2-Q008 | B30: =IF(LEN(B14)=0,"",B14) -> S2-P030
A31: S2-Q009 | B31: =IF(LEN(B15)=0,"",B15) -> S2-P023
A34: Three steps
A35: 1. Match each questionnaire to its established Stage 2 ID. S2-Q numbers identify records, not the player.
A36: 2. Enter Q1–Q9 across the row, record the original form/page in O, and check that its wording matches the guide in P.
A37: 3. Open Results. The workbook calculates each question separately and shows its own valid response count.
A38: A blank is not zero. A confidence score of 0 is a valid answer for Q5 and Q6.
A39: Q4 measures discouragement: a higher score means more discouragement. Q5 and Q6 assume the same staff support.
A40: If the original form differs, retain it and mark Differs. Its answers stay visible but are excluded from these reference-item results.

Sheet Results
A2: Questionnaire results
A3: Each question is calculated separately. Maximum sample: nine questionnaire records.
A4: =IF(SUM('Analysis Data'!M7:M15)=0,"Awaiting answers. Counts are zero; scores and percentages remain blank.",IF(SUM('Analysis Data'!O7:O15)>0,"Provisional: original form wording remains unchecked for some entered records.","Descriptive results for the entered questionnaire records.")) -> Provisional: original form wording remains unchecked for some entered records.
A6: Question | B6: Meaning | C6: Scale | D6: Valid n | E6: Mean | F6: Median | G6: Minimum | H6: Maximum | J6: Record linkage
A7: Q2 | B7: Enjoyment | C7: 1–5 | D7: =COUNTIFS('Analysis Data'!S$7:S$15,"Valid") -> 9 | E7: =IF(D7=0,"",AVERAGE('Analysis Data'!E$7:E$15)) -> 4.3333333 | F7: =IF(D7=0,"",MEDIAN('Analysis Data'!E$7:E$15)) -> 4 | G7: =IF(D7=0,"",MIN('Analysis Data'!E$7:E$15)) -> 4 | H7: =IF(D7=0,"",MAX('Analysis Data'!E$7:E$15)) -> 5 | J7: Resident | K7: =COUNTIFS('Enter Answers'!$C$7:$C$15,J7) -> 9
A8: Q3 | B8: Perceived FRA usefulness | C8: 1–5 | D8: =COUNTIFS('Analysis Data'!T$7:T$15,"Valid") -> 9 | E8: =IF(D8=0,"",AVERAGE('Analysis Data'!F$7:F$15)) -> 4.6666667 | F8: =IF(D8=0,"",MEDIAN('Analysis Data'!F$7:F$15)) -> 5 | G8: =IF(D8=0,"",MIN('Analysis Data'!F$7:F$15)) -> 4 | H8: =IF(D8=0,"",MAX('Analysis Data'!F$7:F$15)) -> 5 | J8: Control | K8: =COUNTIFS('Enter Answers'!$C$7:$C$15,J8) -> 0
A9: Q4 | B9: Discouragement | C9: 1–5 | D9: =COUNTIFS('Analysis Data'!U$7:U$15,"Valid") -> 9 | E9: =IF(D9=0,"",AVERAGE('Analysis Data'!G$7:G$15)) -> 1.8888889 | F9: =IF(D9=0,"",MEDIAN('Analysis Data'!G$7:G$15)) -> 2 | G9: =IF(D9=0,"",MIN('Analysis Data'!G$7:G$15)) -> 1 | H9: =IF(D9=0,"",MAX('Analysis Data'!G$7:G$15)) -> 3 | J9: Unlinked | K9: =COUNTIFS('Enter Answers'!$C$7:$C$15,J9) -> 0
A10: Q5 | B10: Steering confidence | C10: 0–10 | D10: =COUNTIFS('Analysis Data'!V$7:V$15,"Valid") -> 9 | E10: =IF(D10=0,"",AVERAGE('Analysis Data'!H$7:H$15)) -> 7.4444444 | F10: =IF(D10=0,"",MEDIAN('Analysis Data'!H$7:H$15)) -> 8 | G10: =IF(D10=0,"",MIN('Analysis Data'!H$7:H$15)) -> 6 | H10: =IF(D10=0,"",MAX('Analysis Data'!H$7:H$15)) -> 8 | J10: Invalid ID | K10: =COUNTIFS('Enter Answers'!$C$7:$C$15,J10) -> 0
A11: Q6 | B11: Recovery confidence | C11: 0–10 | D11: =COUNTIFS('Analysis Data'!W$7:W$15,"Valid") -> 9 | E11: =IF(D11=0,"",AVERAGE('Analysis Data'!I$7:I$15)) -> 7.6666667 | F11: =IF(D11=0,"",MEDIAN('Analysis Data'!I$7:I$15)) -> 8 | G11: =IF(D11=0,"",MIN('Analysis Data'!I$7:I$15)) -> 6 | H11: =IF(D11=0,"",MAX('Analysis Data'!I$7:I$15)) -> 9 | J11: Duplicate ID | K11: =COUNTIFS('Enter Answers'!$C$7:$C$15,J11) -> 0
A13: Mean = sum of valid scores ÷ valid n. Median = the middle score after ordering the valid scores. | J13: Scope
J14: All questionnaire records
J15: Controls remain identifiable.
A16: Question | B16: Choice | C16: Count | D16: Valid n | E16: Percentage | J16: This is not a resident-only result.
A17: Q7 | B17: Yes | C17: =COUNTIFS('Analysis Data'!$J$7:$J$15,B17,'Analysis Data'!$X$7:$X$15,"Valid") -> 9 | D17: =COUNTIFS('Analysis Data'!$X$7:$X$15,"Valid") -> 9 | E17: =IF(D17=0,"",C17/D17) -> 1
A18: Q7 | B18: Undecided | C18: =COUNTIFS('Analysis Data'!$J$7:$J$15,B18,'Analysis Data'!$X$7:$X$15,"Valid") -> 0 | D18: =COUNTIFS('Analysis Data'!$X$7:$X$15,"Valid") -> 9 | E18: =IF(D18=0,"",C18/D18) -> 0
A19: Q7 | B19: No | C19: =COUNTIFS('Analysis Data'!$J$7:$J$15,B19,'Analysis Data'!$X$7:$X$15,"Valid") -> 0 | D19: =COUNTIFS('Analysis Data'!$X$7:$X$15,"Valid") -> 9 | E19: =IF(D19=0,"",C19/D19) -> 0
A21: Q8 | B21: Willing | C21: =COUNTIFS('Analysis Data'!$K$7:$K$15,B21,'Analysis Data'!$Y$7:$Y$15,"Valid") -> 9 | D21: =COUNTIFS('Analysis Data'!$Y$7:$Y$15,"Valid") -> 9 | E21: =IF(D21=0,"",C21/D21) -> 1
A22: Q8 | B22: Undecided | C22: =COUNTIFS('Analysis Data'!$K$7:$K$15,B22,'Analysis Data'!$Y$7:$Y$15,"Valid") -> 0 | D22: =COUNTIFS('Analysis Data'!$Y$7:$Y$15,"Valid") -> 9 | E22: =IF(D22=0,"",C22/D22) -> 0
A23: Q8 | B23: Unwilling | C23: =COUNTIFS('Analysis Data'!$K$7:$K$15,B23,'Analysis Data'!$Y$7:$Y$15,"Valid") -> 0 | D23: =COUNTIFS('Analysis Data'!$Y$7:$Y$15,"Valid") -> 9 | E23: =IF(D23=0,"",C23/D23) -> 0
A25: Percentage = count selecting an option ÷ valid responses to that question. The denominator can be less than nine.
A28: Agreement score distributions
A29: Score | B29: Q2 count | C29: Q2 % | D29: Q3 count | E29: Q3 % | F29: Q4 count | G29: Q4 %
A30: 1 | B30: =COUNTIFS('Analysis Data'!$E$7:$E$15,$A30,'Analysis Data'!$S$7:$S$15,"Valid") -> 0 | C30: =IF($D$7=0,"",B30/$D$7) -> 0 | D30: =COUNTIFS('Analysis Data'!$F$7:$F$15,$A30,'Analysis Data'!$T$7:$T$15,"Valid") -> 0 | E30: =IF($D$8=0,"",D30/$D$8) -> 0 | F30: =COUNTIFS('Analysis Data'!$G$7:$G$15,$A30,'Analysis Data'!$U$7:$U$15,"Valid") -> 2 | G30: =IF($D$9=0,"",F30/$D$9) -> 0.22222222
A31: 2 | B31: =COUNTIFS('Analysis Data'!$E$7:$E$15,$A31,'Analysis Data'!$S$7:$S$15,"Valid") -> 0 | C31: =IF($D$7=0,"",B31/$D$7) -> 0 | D31: =COUNTIFS('Analysis Data'!$F$7:$F$15,$A31,'Analysis Data'!$T$7:$T$15,"Valid") -> 0 | E31: =IF($D$8=0,"",D31/$D$8) -> 0 | F31: =COUNTIFS('Analysis Data'!$G$7:$G$15,$A31,'Analysis Data'!$U$7:$U$15,"Valid") -> 6 | G31: =IF($D$9=0,"",F31/$D$9) -> 0.66666667
A32: 3 | B32: =COUNTIFS('Analysis Data'!$E$7:$E$15,$A32,'Analysis Data'!$S$7:$S$15,"Valid") -> 0 | C32: =IF($D$7=0,"",B32/$D$7) -> 0 | D32: =COUNTIFS('Analysis Data'!$F$7:$F$15,$A32,'Analysis Data'!$T$7:$T$15,"Valid") -> 0 | E32: =IF($D$8=0,"",D32/$D$8) -> 0 | F32: =COUNTIFS('Analysis Data'!$G$7:$G$15,$A32,'Analysis Data'!$U$7:$U$15,"Valid") -> 1 | G32: =IF($D$9=0,"",F32/$D$9) -> 0.11111111
A33: 4 | B33: =COUNTIFS('Analysis Data'!$E$7:$E$15,$A33,'Analysis Data'!$S$7:$S$15,"Valid") -> 6 | C33: =IF($D$7=0,"",B33/$D$7) -> 0.66666667 | D33: =COUNTIFS('Analysis Data'!$F$7:$F$15,$A33,'Analysis Data'!$T$7:$T$15,"Valid") -> 3 | E33: =IF($D$8=0,"",D33/$D$8) -> 0.33333333 | F33: =COUNTIFS('Analysis Data'!$G$7:$G$15,$A33,'Analysis Data'!$U$7:$U$15,"Valid") -> 0 | G33: =IF($D$9=0,"",F33/$D$9) -> 0
A34: 5 | B34: =COUNTIFS('Analysis Data'!$E$7:$E$15,$A34,'Analysis Data'!$S$7:$S$15,"Valid") -> 3 | C34: =IF($D$7=0,"",B34/$D$7) -> 0.33333333 | D34: =COUNTIFS('Analysis Data'!$F$7:$F$15,$A34,'Analysis Data'!$T$7:$T$15,"Valid") -> 6 | E34: =IF($D$8=0,"",D34/$D$8) -> 0.66666667 | F34: =COUNTIFS('Analysis Data'!$G$7:$G$15,$A34,'Analysis Data'!$U$7:$U$15,"Valid") -> 0 | G34: =IF($D$9=0,"",F34/$D$9) -> 0
A37: Confidence score distributions
A38: Score | B38: Q5 count | C38: Q5 % | D38: Q6 count | E38: Q6 %
A39: 0 | B39: =COUNTIFS('Analysis Data'!$H$7:$H$15,$A39,'Analysis Data'!$V$7:$V$15,"Valid") -> 0 | C39: =IF($D$10=0,"",B39/$D$10) -> 0 | D39: =COUNTIFS('Analysis Data'!$I$7:$I$15,$A39,'Analysis Data'!$W$7:$W$15,"Valid") -> 0 | E39: =IF($D$11=0,"",D39/$D$11) -> 0
A40: 1 | B40: =COUNTIFS('Analysis Data'!$H$7:$H$15,$A40,'Analysis Data'!$V$7:$V$15,"Valid") -> 0 | C40: =IF($D$10=0,"",B40/$D$10) -> 0 | D40: =COUNTIFS('Analysis Data'!$I$7:$I$15,$A40,'Analysis Data'!$W$7:$W$15,"Valid") -> 0 | E40: =IF($D$11=0,"",D40/$D$11) -> 0
A41: 2 | B41: =COUNTIFS('Analysis Data'!$H$7:$H$15,$A41,'Analysis Data'!$V$7:$V$15,"Valid") -> 0 | C41: =IF($D$10=0,"",B41/$D$10) -> 0 | D41: =COUNTIFS('Analysis Data'!$I$7:$I$15,$A41,'Analysis Data'!$W$7:$W$15,"Valid") -> 0 | E41: =IF($D$11=0,"",D41/$D$11) -> 0
A42: 3 | B42: =COUNTIFS('Analysis Data'!$H$7:$H$15,$A42,'Analysis Data'!$V$7:$V$15,"Valid") -> 0 | C42: =IF($D$10=0,"",B42/$D$10) -> 0 | D42: =COUNTIFS('Analysis Data'!$I$7:$I$15,$A42,'Analysis Data'!$W$7:$W$15,"Valid") -> 0 | E42: =IF($D$11=0,"",D42/$D$11) -> 0
A43: 4 | B43: =COUNTIFS('Analysis Data'!$H$7:$H$15,$A43,'Analysis Data'!$V$7:$V$15,"Valid") -> 0 | C43: =IF($D$10=0,"",B43/$D$10) -> 0 | D43: =COUNTIFS('Analysis Data'!$I$7:$I$15,$A43,'Analysis Data'!$W$7:$W$15,"Valid") -> 0 | E43: =IF($D$11=0,"",D43/$D$11) -> 0
A44: 5 | B44: =COUNTIFS('Analysis Data'!$H$7:$H$15,$A44,'Analysis Data'!$V$7:$V$15,"Valid") -> 0 | C44: =IF($D$10=0,"",B44/$D$10) -> 0 | D44: =COUNTIFS('Analysis Data'!$I$7:$I$15,$A44,'Analysis Data'!$W$7:$W$15,"Valid") -> 0 | E44: =IF($D$11=0,"",D44/$D$11) -> 0
A45: 6 | B45: =COUNTIFS('Analysis Data'!$H$7:$H$15,$A45,'Analysis Data'!$V$7:$V$15,"Valid") -> 1 | C45: =IF($D$10=0,"",B45/$D$10) -> 0.11111111 | D45: =COUNTIFS('Analysis Data'!$I$7:$I$15,$A45,'Analysis Data'!$W$7:$W$15,"Valid") -> 1 | E45: =IF($D$11=0,"",D45/$D$11) -> 0.11111111
A46: 7 | B46: =COUNTIFS('Analysis Data'!$H$7:$H$15,$A46,'Analysis Data'!$V$7:$V$15,"Valid") -> 3 | C46: =IF($D$10=0,"",B46/$D$10) -> 0.33333333 | D46: =COUNTIFS('Analysis Data'!$I$7:$I$15,$A46,'Analysis Data'!$W$7:$W$15,"Valid") -> 2 | E46: =IF($D$11=0,"",D46/$D$11) -> 0.22222222
A47: 8 | B47: =COUNTIFS('Analysis Data'!$H$7:$H$15,$A47,'Analysis Data'!$V$7:$V$15,"Valid") -> 5 | C47: =IF($D$10=0,"",B47/$D$10) -> 0.55555556 | D47: =COUNTIFS('Analysis Data'!$I$7:$I$15,$A47,'Analysis Data'!$W$7:$W$15,"Valid") -> 5 | E47: =IF($D$11=0,"",D47/$D$11) -> 0.55555556
A48: 9 | B48: =COUNTIFS('Analysis Data'!$H$7:$H$15,$A48,'Analysis Data'!$V$7:$V$15,"Valid") -> 0 | C48: =IF($D$10=0,"",B48/$D$10) -> 0 | D48: =COUNTIFS('Analysis Data'!$I$7:$I$15,$A48,'Analysis Data'!$W$7:$W$15,"Valid") -> 1 | E48: =IF($D$11=0,"",D48/$D$11) -> 0.11111111
A49: 10 | B49: =COUNTIFS('Analysis Data'!$H$7:$H$15,$A49,'Analysis Data'!$V$7:$V$15,"Valid") -> 0 | C49: =IF($D$10=0,"",B49/$D$10) -> 0 | D49: =COUNTIFS('Analysis Data'!$I$7:$I$15,$A49,'Analysis Data'!$W$7:$W$15,"Valid") -> 0 | E49: =IF($D$11=0,"",D49/$D$11) -> 0
...

Sheet Question Guide
A2: Question guide and calculation rules
A3: Nine numbered questions. Contact permission is a separate administrative prompt.
A6: Question | B6: Topic | C6: Original Chinese wording | D6: English wording | E6: How to enter | F6: Source
A7: Q01 | B7: Memorable experience | C7: 今天玩遊戲，甚麼令您印象最深？ | D7: What stood out most to you when playing the game today? | E7: Write the original answer in Enter Answers D. | F7: Reference 1
A8: Q02 | B8: Game enjoyment | C8: 我覺得玩這個遊戲有樂趣。 | D8: I find playing this game enjoyable. | E8: Enter the selected integer 1–5 in E. | F8: Reference 1
A9: Q03 | B9: Perceived usefulness of FRA | C9: 我認為跌倒風險評估有助我了解自己的平衡能力。 | D9: I think fall risk assessment helps me understand my balance ability. | E9: Enter the selected integer 1–5 in F. | F9: Reference 1
A10: Q04 | B10: Discouragement after disappointing performance | C10: 遊戲表現不如我所願時，我感到氣餒。 | D10: When my game performance is not as I would like, I feel discouraged. | E10: Enter the selected integer 1–5 in G. Higher means more discouraged. | F10: Reference 1
A11: Q05 | B11: Steering confidence with staff support | C11: 把滑雪角色轉向我想去的方向。 | D11: Steer the skiing character in the direction I want to go. | E11: Enter the selected integer 0–10 in H, assuming the same staff support. | F11: Reference 1
A12: Q06 | B12: Recovery confidence with staff support | C12: 轉向失誤後，重新控制滑雪角色。 | D12: Regain control of the skiing character after a steering error. | E12: Enter the selected integer 0–10 in I, assuming the same staff support. | F12: Reference 1
A13: Q07 | B13: Intention to play again | C13: 下次有機會參加時，您想再玩這個滑雪遊戲嗎？ | D13: When you next have an opportunity to participate, would you like to play this skiing game again? | E13: Choose Yes / Undecided / No in J. Chinese: 想 / 未確定 / 不想. | F13: Reference 1
A14: Q08 | B14: Willingness to receive FRA again | C14: 您願意再次接受跌倒風險評估，了解自己的平衡能力嗎？ | D14: Would you be willing to receive fall risk assessment again to understand your balance ability? | E14: Choose Willing / Undecided / Unwilling in K. Chinese: 願意 / 未確定 / 不願意. | F14: Reference 1
A15: Q09 | B15: Reasons for replay and assessment choices | C15: 您對再次玩遊戲及再次接受評估的選擇，主要原因是甚麼？ | D15: What are the main reasons for your choices about playing the game again and receiving assessment again? | E15: Write the original answer in L. Preserve reasons for both replay and FRA choices. | F15: Reference 1
A18: Scales
A19: Agreement: 1 Strongly disagree; 2 Disagree; 3 Neither agree nor disagree; 4 Agree; 5 Strongly agree.
A20: Confidence: 0 No confidence at all; 5 Moderate confidence; 10 Completely confident.
A21: The confidence questions assume the same staff support as at the questionnaire session.
A23: Data entry and missing answers
A24: Each row is one respondent record. Each question has its own answer column. Enter all nine answers across the row.
A25: Copy long answers into Q1 or Q9 as written. Expand the row height if needed to view the full text.
A26: If an answer is absent, leave its answer cell empty and select the documented reason in the grid below.
A27: An untouched blank means Not entered. Not recorded means the original record does not contain the answer.
A28: Not applicable is offered for Q2–Q4; for Q4 it applies if the respondent had no such disappointing experience.
A29: Do not enter a score and a missing-answer reason for the same item. Such conflicts are flagged and excluded.
A30: Permission to contact is entered in M, separately from Q1–Q9. It does not establish interview consent or completion.
... A61: The earlier questionnaire workbook retains the full interview evidence framework. This simpler file is for entry and descriptive questionnaire results.

Sheet Analysis Data
A2: Analysis data and item checks
A3: Calculated from Enter Answers. These cells preserve zero and exclude invalid values, conflicts and explicitly different forms.
A6: Questionnaire record | B6: Stage 2 player ID | C6: Record type | D6: Q1 Memorable experience | E6: Q2 Enjoyment 1–5 | F6: Q3 FRA usefulness 1–5 | G6: Q4 Discouragement 1–5 | H6: Q5 Steering confidence 0–10 | I6: Q6 Recovery confidence 0–10 | J6: Q7 Play again | K6: Q8 FRA again | L6: Q9 Reasons | M6: Answers entered | N6: Corrections needed | O6: Form check pending | P6: Form wording checked | R6: Q01 status | S6: Q02 status | T6: Q03 status | U6: Q04 status | V6: Q05 status | W6: Q06 status | X6: Q07 status | Y6: Q08 status | Z6: Q09 status
A7: =IF(LEN('Enter Answers'!A7)=0,"",'Enter Answers'!A7) -> S2-Q001 | B7: =IF(LEN('Enter Answers'!B7)=0,"",'Enter Answers'!B7) -> S2-P024 | C7: =IF(LEN('Enter Answers'!C7)=0,"",'Enter Answers'!C7) -> Resident | D7: =IF(R7="Valid",'Enter Answers'!D7,"") -> 好玩，有用。知道如何同步。滑雪如何真實畫面就更好。 | E7: =IF(S7="Valid",'Enter Answers'!E7,"") -> 4 | F7: =IF(T7="Valid",'Enter Answers'!F7,"") -> 4 | G7: =IF(U7="Valid",'Enter Answers'!G7,"") -> 2 | H7: =IF(V7="Valid",'Enter Answers'!H7,"") -> 8 | I7: =IF(W7="Valid",'Enter Answers'!I7,"") -> 8 | J7: =IF(X7="Valid",'Enter Answers'!J7,"") -> Yes | K7: =IF(Y7="Valid",'Enter Answers'!K7,"") -> Willing | L7: =IF(Z7="Valid",'Enter Answers'!L7,"") -> 好想繼續玩，因為，可以繼續鍛鍊，提高自己的防跌倒能力 | M7: =9-COUNTBLANK('Enter Answers'!D7:L7) -> 9 | N7: =COUNTIFS(R7:Z7,"Invalid value")+COUNTIFS(R7:Z7,"Answer/status conflict")+COUNTIFS(R7:Z7,"Different form") -> 0 | O7: =IF(AND(M7>0,P7<>"Matches"),1,0) -> 1 | P7: =IF(LEN('Enter Answers'!O7)=0,"",'Enter Answers'!O7) -> Not checked | R7: =IF(LEN('Enter Answers'!D7)=0,IF(LEN('Enter Answers'!D23)=0,"Not entered",'Enter Answers'!D23),IF('Enter Answers'!O7="Differs","Different form",IF(LEN('Enter Answers'!D23)>0,"Answer/status conflict",IF(TRUE,"Valid","Invalid value")))) -> Valid | S7: =IF(LEN('Enter Answers'!E7)=0,IF(LEN('Enter Answers'!E23)=0,"Not entered",'Enter Answers'!E23),IF('Enter Answers'!O7="Differs","Different form",IF(LEN('Enter Answers'!E23)>0,"Answer/status conflict",IF(IF(ISNUMBER('Enter Answers'!E7),AND('Enter Answers'!E7>=1,'Enter Answers'!E7<=5,MOD('Enter Answers'!E7,1)=0),FALSE),"Valid","Invalid value")))) -> Valid | T7: =IF(LEN('Enter Answers'!F7)=0,IF(LEN('Enter Answers'!F23)=0,"Not entered",'Enter Answers'!F23),IF('Enter Answers'!O7="Differs","Different form",IF(LEN('Enter Answers'!F23)>0,"Answer/status conflict",IF(IF(ISNUMBER('Enter Answers'!F7),AND('Enter Answers'!F7>=1,'Enter Answers'!F7<=5,MOD('Enter Answers'!F7,1)=0),FALSE),"Valid","Invalid value")))) -> Valid | U7: =IF(LEN('Enter Answers'!G7)=0,IF(LEN('Enter Answers'!G23)=0,"Not entered",'Enter Answers'!G23),IF('Enter Answers'!O7="Differs","Different form",IF(LEN('Enter Answers'!G23)>0,"Answer/status conflict",IF(IF(ISNUMBER('Enter Answers'!G7),AND('Enter Answers'!G7>=1,'Enter Answers'!G7<=5,MOD('Enter Answers'!G7,1)=0),FALSE),"Valid","Invalid value")))) -> Valid | V7: =IF(LEN('Enter Answers'!H7)=0,IF(LEN('Enter Answers'!H23)=0,"Not entered",'Enter Answers'!H23),IF('Enter Answers'!O7="Differs","Different form",IF(LEN('Enter Answers'!H23)>0,"Answer/status conflict",IF(IF(ISNUMBER('Enter Answers'!H7),AND('Enter Answers'!H7>=0,'Enter Answers'!H7<=10,MOD('Enter Answers'!H7,1)=0),FALSE),"Valid","Invalid value")))) -> Valid | W7: =IF(LEN('Enter Answers'!I7)=0,IF(LEN('Enter Answers'!I23)=0,"Not entered",'Enter Answers'!I23),IF('Enter Answers'!O7="Differs","Different form",IF(LEN('Enter Answers'!I23)>0,"Answer/status conflict",IF(IF(ISNUMBER('Enter Answers'!I7),AND('Enter Answers'!I7>=0,'Enter Answers'!I7<=10,MOD('Enter Answers'!I7,1)=0),FALSE),"Valid","Invalid value")))) -> Valid | X7: =IF(LEN('Enter Answers'!J7)=0,IF(LEN('Enter Answers'!J23)=0,"Not entered",'Enter Answers'!J23),IF('Enter Answers'!O7="Differs","Different form",IF(LEN('Enter Answers'!J23)>0,"Answer/status conflict",IF(OR('Enter Answers'!J7="Yes",'Enter Answers'!J7="Undecided",'Enter Answers'!J7="No"),"Valid","Invalid value")))) -> Valid | Y7: =IF(LEN('Enter Answers'!K7)=0,IF(LEN('Enter Answers'!K23)=0,"Not entered",'Enter Answers'!K23),IF('Enter Answers'!O7="Differs","Different form",IF(LEN('Enter Answers'!K23)>0,"Answer/status conflict",IF(OR('Enter Answers'!K7="Willing",'Enter Answers'!K7="Undecided",'Enter Answers'!K7="Unwilling"),"Valid","Invalid value")))) -> Valid | Z7: =IF(LEN('Enter Answers'!L7)=0,IF(LEN('Enter Answers'!L23)=0,"Not entered",'Enter Answers'!L23),IF('Enter Answers'!O7="Differs","Different form",IF(LEN('Enter Answers'!L23)>0,"Answer/status conflict",IF(TRUE,"Valid","Invalid value")))) -> Valid
A8: =IF(LEN('Enter Answers'!A8)=0,"",'Enter Answers'!A8) -> S2-Q002 | B8: =IF(LEN('Enter Answers'!B8)=0,"",'Enter Answers'!B8) -> S2-P025 | C8: =IF(LEN('Enter Answers'!C8)=0,"",'Enter Answers'!C8) -> Resident | D8: =IF(R8="Valid",'Enter Answers'!D8,"") -> 好玩，有用。滑雪畫面一般，唔夠吸引。 | E8: =IF(S8="Valid",'Enter Answers'!E8,"") -> 4 | F8: =IF(T8="Valid",'Enter Answers'!F8,"") -> 5 | G8: =IF(U8="Valid",'Enter Answers'!G8,"") -> 3 | H8: =IF(V8="Valid",'Enter Answers'!H8,"") -> 7 | I8: =IF(W8="Valid",'Enter Answers'!I8,"") -> 8 | J8: =IF(X8="Valid",'Enter Answers'!J8,"") -> Yes | K8: =IF(Y8="Valid",'Enter Answers'!K8,"") -> Willing | L8: =IF(Z8="Valid",'Enter Answers'!L8,"") -> 玩完知道分數比較開心，成績不錯 | M8: =9-COUNTBLANK('Enter Answers'!D8:L8) -> 9 | N8: =COUNTIFS(R8:Z8,"Invalid value")+COUNTIFS(R8:Z8,"Answer/status conflict")+COUNTIFS(R8:Z8,"Different form") -> 0 | O8: =IF(AND(M8>0,P8<>"Matches"),1,0) -> 1 | P8: =IF(LEN('Enter Answers'!O8)=0,"",'Enter Answers'!O8) -> Not checked | R8: =IF(LEN('Enter Answers'!D8)=0,IF(LEN('Enter Answers'!D24)=0,"Not entered",'Enter Answers'!D24),IF('Enter Answers'!O8="Differs","Different form",IF(LEN('Enter Answers'!D24)>0,"Answer/status conflict",IF(TRUE,"Valid","Invalid value")))) -> Valid | S8: =IF(LEN('Enter Answers'!E8)=0,IF(LEN('Enter Answers'!E24)=0,"Not entered",'Enter Answers'!E24),IF('Enter Answers'!O8="Differs","Different form",IF(LEN('Enter Answers'!E24)>0,"Answer/status conflict",IF(IF(ISNUMBER('Enter Answers'!E8),AND('Enter Answers'!E8>=1,'Enter Answers'!E8<=5,MOD('Enter Answers'!E8,1)=0),FALSE),"Valid","Invalid value")))) -> Valid | T8: =IF(LEN('Enter Answers'!F8)=0,IF(LEN('Enter Answers'!F24)=0,"Not entered",'Enter Answers'!F24),IF('Enter Answers'!O8="Differs","Different form",IF(LEN('Enter Answers'!F24)>0,"Answer/status conflict",IF(IF(ISNUMBER('Enter Answers'!F8),AND('Enter Answers'!F8>=1,'Enter Answers'!F8<=5,MOD('Enter Answers'!F8,1)=0),FALSE),"Valid","Invalid value")))) -> Valid | U8: =IF(LEN('Enter Answers'!G8)=0,IF(LEN('Enter Answers'!G24)=0,"Not entered",'Enter Answers'!G24),IF('Enter Answers'!O8="Differs","Different form",IF(LEN('Enter Answers'!G24)>0,"Answer/status conflict",IF(IF(ISNUMBER('Enter Answers'!G8),AND('Enter Answers'!G8>=1,'Enter Answers'!G8<=5,MOD('Enter Answers'!G8,1)=0),FALSE),"Valid","Invalid value")))) -> Valid | V8: =IF(LEN('Enter Answers'!H8)=0,IF(LEN('Enter Answers'!H24)=0,"Not entered",'Enter Answers'!H24),IF('Enter Answers'!O8="Differs","Different form",IF(LEN('Enter Answers'!H24)>0,"Answer/status conflict",IF(IF(ISNUMBER('Enter Answers'!H8),AND('Enter Answers'!H8>=0,'Enter Answers'!H8<=10,MOD('Enter Answers'!H8,1)=0),FALSE),"Valid","Invalid value")))) -> Valid | W8: =IF(LEN('Enter Answers'!I8)=0,IF(LEN('Enter Answers'!I24)=0,"Not entered",'Enter Answers'!I24),IF('Enter Answers'!O8="Differs","Different form",IF(LEN('Enter Answers'!I24)>0,"Answer/status conflict",IF(IF(ISNUMBER('Enter Answers'!I8),AND('Enter Answers'!I8>=0,'Enter Answers'!I8<=10,MOD('Enter Answers'!I8,1)=0),FALSE),"Valid","Invalid value")))) -> Valid | X8: =IF(LEN('Enter Answers'!J8)=0,IF(LEN('Enter Answers'!J24)=0,"Not entered",'Enter Answers'!J24),IF('Enter Answers'!O8="Differs","Different form",IF(LEN('Enter Answers'!J24)>0,"Answer/status conflict",IF(OR('Enter Answers'!J8="Yes",'Enter Answers'!J8="Undecided",'Enter Answers'!J8="No"),"Valid","Invalid value")))) -> Valid | Y8: =IF(LEN('Enter Answers'!K8)=0,IF(LEN('Enter Answers'!K24)=0,"Not entered",'Enter Answers'!K24),IF('Enter Answers'!O8="Differs","Different form",IF(LEN('Enter Answers'!K24)>0,"Answer/status conflict",IF(OR('Enter Answers'!K8="Willing",'Enter Answers'!K8="Undecided",'Enter Answers'!K8="Unwilling"),"Valid","Invalid value")))) -> Valid | Z8: =IF(LEN('Enter Answers'!L8)=0,IF(LEN('Enter Answers'!L24)=0,"Not entered",'Enter Answers'!L24),IF('Enter Answers'!O8="Differs","Different form",IF(LEN('Enter Answers'!L24)>0,"Answer/status conflict",IF(TRUE,"Valid","Invalid value")))) -> Valid
A9: =IF(LEN('Enter Answers'!A9)=0,"",'Enter Answers'!A9) -> S2-Q003 | B9: =IF(LEN('Enter Answers'!B9)=0,"",'Enter Answers'!B9) -> S2-P013 | C9: =IF(LEN('Enter Answers'!C9)=0,"",'Enter Answers'!C9) -> Resident | D9: =IF(R9="Valid",'Enter Answers'!D9,"") -> 好玩，有用。知道如何平衡。 | E9: =IF(S9="Valid",'Enter Answers'!E9,"") -> 4 | F9: =IF(T9="Valid",'Enter Answers'!F9,"") -> 5 | G9: =IF(U9="Valid",'Enter Answers'!G9,"") -> 2 | H9: =IF(V9="Valid",'Enter Answers'!H9,"") -> 7 | I9: =IF(W9="Valid",'Enter Answers'!I9,"") -> 7 | J9: =IF(X9="Valid",'Enter Answers'!J9,"") -> Yes | K9: =IF(Y9="Valid",'Enter Answers'!K9,"") -> Willing | L9: =IF(Z9="Valid",'Enter Answers'!L9,"") -> 唔錯的遊戲。 用了培訓不錯。 | M9: =9-COUNTBLANK('Enter Answers'!D9:L9) -> 9 | N9: =COUNTIFS(R9:Z9,"Invalid value")+COUNTIFS(R9:Z9,"Answer/status conflict")+COUNTIFS(R9:Z9,"Different form") -> 0 | O9: =IF(AND(M9>0,P9<>"Matches"),1,0) -> 1 | P9: =IF(LEN('Enter Answers'!O9)=0,"",'Enter Answers'!O9) -> Not checked | R9: =IF(LEN('Enter Answers'!D9)=0,IF(LEN('Enter Answers'!D25)=0,"Not entered",'Enter Answers'!D25),IF('Enter Answers'!O9="Differs","Different form",IF(LEN('Enter Answers'!D25)>0,"Answer/status conflict",IF(TRUE,"Valid","Invalid value")))) -> Valid | S9: =IF(LEN('Enter Answers'!E9)=0,IF(LEN('Enter Answers'!E25)=0,"Not entered",'Enter Answers'!E25),IF('Enter Answers'!O9="Differs","Different form",IF(LEN('Enter Answers'!E25)>0,"Answer/status conflict",IF(IF(ISNUMBER('Enter Answers'!E9),AND('Enter Answers'!E9>=1,'Enter Answers'!E9<=5,MOD('Enter Answers'!E9,1)=0),FALSE),"Valid","Invalid value")))) -> Valid | T9: =IF(LEN('Enter Answers'!F9)=0,IF(LEN('Enter Answers'!F25)=0,"Not entered",'Enter Answers'!F25),IF('Enter Answers'!O9="Differs","Different form",IF(LEN('Enter Answers'!F25)>0,"Answer/status conflict",IF(IF(ISNUMBER('Enter Answers'!F9),AND('Enter Answers'!F9>=1,'Enter Answers'!F9<=5,MOD('Enter Answers'!F9,1)=0),FALSE),"Valid","Invalid value")))) -> Valid | U9: =IF(LEN('Enter Answers'!G9)=0,IF(LEN('Enter Answers'!G25)=0,"Not entered",'Enter Answers'!G25),IF('Enter Answers'!O9="Differs","Different form",IF(LEN('Enter Answers'!G25)>0,"Answer/status conflict",IF(IF(ISNUMBER('Enter Answers'!G9),AND('Enter Answers'!G9>=1,'Enter Answers'!G9<=5,MOD('Enter Answers'!G9,1)=0),FALSE),"Valid","Invalid value")))) -> Valid | V9: =IF(LEN('Enter Answers'!H9)=0,IF(LEN('Enter Answers'!H25)=0,"Not entered",'Enter Answers'!H25),IF('Enter Answers'!O9="Differs","Different form",IF(LEN('Enter Answers'!H25)>0,"Answer/status conflict",IF(IF(ISNUMBER('Enter Answers'!H9),AND('Enter Answers'!H9>=0,'Enter Answers'!H9<=10,MOD('Enter Answers'!H9,1)=0),FALSE),"Valid","Invalid value")))) -> Valid | W9: =IF(LEN('Enter Answers'!I9)=0,IF(LEN('Enter Answers'!I25)=0,"Not entered",'Enter Answers'!I25),IF('Enter Answers'!O9="Differs","Different form",IF(LEN('Enter Answers'!I25)>0,"Answer/status conflict",IF(IF(ISNUMBER('Enter Answers'!I9),AND('Enter Answers'!I9>=0,'Enter Answers'!I9<=10,MOD('Enter Answers'!I9,1)=0),FALSE),"Valid","Invalid value")))) -> Valid | X9: =IF(LEN('Enter Answers'!J9)=0,IF(LEN('Enter Answers'!J25)=0,"Not entered",'Enter Answers'!J25),IF('Enter Answers'!O9="Differs","Different form",IF(LEN('Enter Answers'!J25)>0,"Answer/status conflict",IF(OR('Enter Answers'!J9="Yes",'Enter Answers'!J9="Undecided",'Enter Answers'!J9="No"),"Valid","Invalid value")))) -> Valid | Y9: =IF(LEN('Enter Answers'!K9)=0,IF(LEN('Enter Answers'!K25)=0,"Not entered",'Enter Answers'!K25),IF('Enter Answers'!O9="Differs","Different form",IF(LEN('Enter Answers'!K25)>0,"Answer/status conflict",IF(OR('Enter Answers'!K9="Willing",'Enter Answers'!K9="Undecided",'Enter Answers'!K9="Unwilling"),"Valid","Invalid value")))) -> Valid | Z9: =IF(LEN('Enter Answers'!L9)=0,IF(LEN('Enter Answers'!L25)=0,"Not entered",'Enter Answers'!L25),IF('Enter Answers'!O9="Differs","Different form",IF(LEN('Enter Answers'!L25)>0,"Answer/status conflict",IF(TRUE,"Valid","Invalid value")))) -> Valid
A10: =IF(LEN('Enter Answers'!A10)=0,"",'Enter Answers'!A10) -> S2-Q004 | B10: =IF(LEN('Enter Answers'!B10)=0,"",'Enter Answers'!B10) -> S2-P005 | C10: =IF(LEN('Enter Answers'!C10)=0,"",'Enter Answers'!C10) -> Resident | D10: =IF(R10="Valid",'Enter Answers'!D10,"") -> 好玩，有用。知道如何平衡更有效。畫面比較弱。 | E10: =IF(S10="Valid",'Enter Answers'!E10,"") -> 4 | F10: =IF(T10="Valid",'Enter Answers'!F10,"") -> 4 | G10: =IF(U10="Valid",'Enter Answers'!G10,"") -> 2 | H10: =IF(V10="Valid",'Enter Answers'!H10,"") -> 8 | I10: =IF(W10="Valid",'Enter Answers'!I10,"") -> 8 | J10: =IF(X10="Valid",'Enter Answers'!J10,"") -> Yes | K10: =IF(Y10="Valid",'Enter Answers'!K10,"") -> Willing | L10: =IF(Z10="Valid",'Enter Answers'!L10,"") -> 有用。幾有用？就好難講。感覺不錯。 | M10: =9-COUNTBLANK('Enter Answers'!D10:L10) -> 9 | N10: =COUNTIFS(R10:Z10,"Invalid value")+COUNTIFS(R10:Z10,"Answer/status conflict")+COUNTIFS(R10:Z10,"Different form") -> 0 | O10: =IF(AND(M10>0,P10<>"Matches"),1,0) -> 1 | P10: =IF(LEN('Enter Answers'!O10)=0,"",'Enter Answers'!O10) -> Not checked | R10: =IF(LEN('Enter Answers'!D10)=0,IF(LEN('Enter Answers'!D26)=0,"Not entered",'Enter Answers'!D26),IF('Enter Answers'!O10="Differs","Different form",IF(LEN('Enter Answers'!D26)>0,"Answer/status conflict",IF(TRUE,"Valid","Invalid value")))) -> Valid | S10: =IF(LEN('Enter Answers'!E10)=0,IF(LEN('Enter Answers'!E26)=0,"Not entered",'Enter Answers'!E26),IF('Enter Answers'!O10="Differs","Different form",IF(LEN('Enter Answers'!E26)>0,"Answer/status conflict",IF(IF(ISNUMBER('Enter Answers'!E10),AND('Enter Answers'!E10>=1,'Enter Answers'!E10<=5,MOD('Enter Answers'!E10,1)=0),FALSE),"Valid","Invalid value")))) -> Valid | T10: =IF(LEN('Enter Answers'!F10)=0,IF(LEN('Enter Answers'!F26)=0,"Not entered",'Enter Answers'!F26),IF('Enter Answers'!O10="Differs","Different form",IF(LEN('Enter Answers'!F26)>0,"Answer/status conflict",IF(IF(ISNUMBER('Enter Answers'!F10),AND('Enter Answers'!F10>=1,'Enter Answers'!F10<=5,MOD('Enter Answers'!F10,1)=0),FALSE),"Valid","Invalid value")))) -> Valid | U10: =IF(LEN('Enter Answers'!G10)=0,IF(LEN('Enter Answers'!G26)=0,"Not entered",'Enter Answers'!G26),IF('Enter Answers'!O10="Differs","Different form",IF(LEN('Enter Answers'!G26)>0,"Answer/status conflict",IF(IF(ISNUMBER('Enter Answers'!G10),AND('Enter Answers'!G10>=1,'Enter Answers'!G10<=5,MOD('Enter Answers'!G10,1)=0),FALSE),"Valid","Invalid value")))) -> Valid | V10: =IF(LEN('Enter Answers'!H10)=0,IF(LEN('Enter Answers'!H26)=0,"Not entered",'Enter Answers'!H26),IF('Enter Answers'!O10="Differs","Different form",IF(LEN('Enter Answers'!H26)>0,"Answer/status conflict",IF(IF(ISNUMBER('Enter Answers'!H10),AND('Enter Answers'!H10>=0,'Enter Answers'!H10<=10,MOD('Enter Answers'!H10,1)=0),FALSE),"Valid","Invalid value")))) -> Valid | W10: =IF(LEN('Enter Answers'!I10)=0,IF(LEN('Enter Answers'!I26)=0,"Not entered",'Enter Answers'!I26),IF('Enter Answers'!O10="Differs","Different form",IF(LEN('Enter Answers'!I26)>0,"Answer/status conflict",IF(IF(ISNUMBER('Enter Answers'!I10),AND('Enter Answers'!I10>=0,'Enter Answers'!I10<=10,MOD('Enter Answers'!I10,1)=0),FALSE),"Valid","Invalid value")))) -> Valid | X10: =IF(LEN('Enter Answers'!J10)=0,IF(LEN('Enter Answers'!J26)=0,"Not entered",'Enter Answers'!J26),IF('Enter Answers'!O10="Differs","Different form",IF(LEN('Enter Answers'!J26)>0,"Answer/status conflict",IF(OR('Enter Answers'!J10="Yes",'Enter Answers'!J10="Undecided",'Enter Answers'!J10="No"),"Valid","Invalid value")))) -> Valid | Y10: =IF(LEN('Enter Answers'!K10)=0,IF(LEN('Enter Answers'!K26)=0,"Not entered",'Enter Answers'!K26),IF('Enter Answers'!O10="Differs","Different form",IF(LEN('Enter Answers'!K26)>0,"Answer/status conflict",IF(OR('Enter Answers'!K10="Willing",'Enter Answers'!K10="Undecided",'Enter Answers'!K10="Unwilling"),"Valid","Invalid value")))) -> Valid | Z10: =IF(LEN('Enter Answers'!L10)=0,IF(LEN('Enter Answers'!L26)=0,"Not entered",'Enter Answers'!L26),IF('Enter Answers'!O10="Differs","Different form",IF(LEN('Enter Answers'!L26)>0,"Answer/status conflict",IF(TRUE,"Valid","Invalid value")))) -> Valid
A11: =IF(LEN('Enter Answers'!A11)=0,"",'Enter Answers'!A11) -> S2-Q005 | B11: =IF(LEN('Enter Answers'!B11)=0,"",'Enter Answers'!B11) -> S2-P014 | C11: =IF(LEN('Enter Answers'!C11)=0,"",'Enter Answers'!C11) -> Resident | D11: =IF(R11="Valid",'Enter Answers'!D11,"") -> 好玩，有用。玩左幾次。 | E11: =IF(S11="Valid",'Enter Answers'!E11,"") -> 5 | F11: =IF(T11="Valid",'Enter Answers'!F11,"") -> 5 | G11: =IF(U11="Valid",'Enter Answers'!G11,"") -> 2 | H11: =IF(V11="Valid",'Enter Answers'!H11,"") -> 8 | I11: =IF(W11="Valid",'Enter Answers'!I11,"") -> 8 | J11: =IF(X11="Valid",'Enter Answers'!J11,"") -> Yes | K11: =IF(Y11="Valid",'Enter Answers'!K11,"") -> Willing | L11: =IF(Z11="Valid",'Enter Answers'!L11,"") -> 有D人唔試，真系唔知點解。幾有用。可以鍛鍊，集中精神 | M11: =9-COUNTBLANK('Enter Answers'!D11:L11) -> 9 | N11: =COUNTIFS(R11:Z11,"Invalid value")+COUNTIFS(R11:Z11,"Answer/status conflict")+COUNTIFS(R11:Z11,"Different form") -> 0 | O11: =IF(AND(M11>0,P11<>"Matches"),1,0) -> 1 | P11: =IF(LEN('Enter Answers'!O11)=0,"",'Enter Answers'!O11) -> Not checked | R11: =IF(LEN('Enter Answers'!D11)=0,IF(LEN('Enter Answers'!D27)=0,"Not entered",'Enter Answers'!D27),IF('Enter Answers'!O11="Differs","Different form",IF(LEN('Enter Answers'!D27)>0,"Answer/status conflict",IF(TRUE,"Valid","Invalid value")))) -> Valid | S11: =IF(LEN('Enter Answers'!E11)=0,IF(LEN('Enter Answers'!E27)=0,"Not entered",'Enter Answers'!E27),IF('Enter Answers'!O11="Differs","Different form",IF(LEN('Enter Answers'!E27)>0,"Answer/status conflict",IF(IF(ISNUMBER('Enter Answers'!E11),AND('Enter Answers'!E11>=1,'Enter Answers'!E11<=5,MOD('Enter Answers'!E11,1)=0),FALSE),"Valid","Invalid value")))) -> Valid | T11: =IF(LEN('Enter Answers'!F11)=0,IF(LEN('Enter Answers'!F27)=0,"Not entered",'Enter Answers'!F27),IF('Enter Answers'!O11="Differs","Different form",IF(LEN('Enter Answers'!F27)>0,"Answer/status conflict",IF(IF(ISNUMBER('Enter Answers'!F11),AND('Enter Answers'!F11>=1,'Enter Answers'!F11<=5,MOD('Enter Answers'!F11,1)=0),FALSE),"Valid","Invalid value")))) -> Valid | U11: =IF(LEN('Enter Answers'!G11)=0,IF(LEN('Enter Answers'!G27)=0,"Not entered",'Enter Answers'!G27),IF('Enter Answers'!O11="Differs","Different form",IF(LEN('Enter Answers'!G27)>0,"Answer/status conflict",IF(IF(ISNUMBER('Enter Answers'!G11),AND('Enter Answers'!G11>=1,'Enter Answers'!G11<=5,MOD('Enter Answers'!G11,1)=0),FALSE),"Valid","Invalid value")))) -> Valid | V11: =IF(LEN('Enter Answers'!H11)=0,IF(LEN('Enter Answers'!H27)=0,"Not entered",'Enter Answers'!H27),IF('Enter Answers'!O11="Differs","Different form",IF(LEN('Enter Answers'!H27)>0,"Answer/status conflict",IF(IF(ISNUMBER('Enter Answers'!H11),AND('Enter Answers'!H11>=0,'Enter Answers'!H11<=10,MOD('Enter Answers'!H11,1)=0),FALSE),"Valid","Invalid value")))) -> Valid | W11: =IF(LEN('Enter Answers'!I11)=0,IF(LEN('Enter Answers'!I27)=0,"Not entered",'Enter Answers'!I27),IF('Enter Answers'!O11="Differs","Different form",IF(LEN('Enter Answers'!I27)>0,"Answer/status conflict",IF(IF(ISNUMBER('Enter Answers'!I11),AND('Enter Answers'!I11>=0,'Enter Answers'!I11<=10,MOD('Enter Answers'!I11,1)=0),FALSE),"Valid","Invalid value")))) -> Valid | X11: =IF(LEN('Enter Answers'!J11)=0,IF(LEN('Enter Answers'!J27)=0,"Not entered",'Enter Answers'!J27),IF('Enter Answers'!O11="Differs","Different form",IF(LEN('Enter Answers'!J27)>0,"Answer/status conflict",IF(OR('Enter Answers'!J11="Yes",'Enter Answers'!J11="Undecided",'Enter Answers'!J11="No"),"Valid","Invalid value")))) -> Valid | Y11: =IF(LEN('Enter Answers'!K11)=0,IF(LEN('Enter Answers'!K27)=0,"Not entered",'Enter Answers'!K27),IF('Enter Answers'!O11="Differs","Different form",IF(LEN('Enter Answers'!K27)>0,"Answer/status conflict",IF(OR('Enter Answers'!K11="Willing",'Enter Answers'!K11="Undecided",'Enter Answers'!K11="Unwilling"),"Valid","Invalid value")))) -> Valid | Z11: =IF(LEN('Enter Answers'!L11)=0,IF(LEN('Enter Answers'!L27)=0,"Not entered",'Enter Answers'!L27),IF('Enter Answers'!O11="Differs","Different form",IF(LEN('Enter Answers'!L27)>0,"Answer/status conflict",IF(TRUE,"Valid","Invalid value")))) -> Valid
A12: =IF(LEN('Enter Answers'!A12)=0,"",'Enter Answers'!A12) -> S2-Q006 | B12: =IF(LEN('Enter Answers'!B12)=0,"",'Enter Answers'!B12) -> S2-P004 | C12: =IF(LEN('Enter Answers'!C12)=0,"",'Enter Answers'!C12) -> Resident | D12: =IF(R12="Valid",'Enter Answers'!D12,"") -> 好玩，有用。好似好容易，其實有挑戰。畫面要改進。 | E12: =IF(S12="Valid",'Enter Answers'!E12,"") -> 5 | F12: =IF(T12="Valid",'Enter Answers'!F12,"") -> 5 | G12: =IF(U12="Valid",'Enter Answers'!G12,"") -> 1 | H12: =IF(V12="Valid",'Enter Answers'!H12,"") -> 8 | I12: =IF(W12="Valid",'Enter Answers'!I12,"") -> 9 | J12: =IF(X12="Valid",'Enter Answers'!J12,"") -> Yes | K12: =IF(Y12="Valid",'Enter Answers'!K12,"") -> Willing | L12: =IF(Z12="Valid",'Enter Answers'!L12,"") -> 有用。幾有用？就好難講。比以前進步。 | M12: =9-COUNTBLANK('Enter Answers'!D12:L12) -> 9 | N12: =COUNTIFS(R12:Z12,"Invalid value")+COUNTIFS(R12:Z12,"Answer/status conflict")+COUNTIFS(R12:Z12,"Different form") -> 0 | O12: =IF(AND(M12>0,P12<>"Matches"),1,0) -> 1 | P12: =IF(LEN('Enter Answers'!O12)=0,"",'Enter Answers'!O12) -> Not checked | R12: =IF(LEN('Enter Answers'!D12)=0,IF(LEN('Enter Answers'!D28)=0,"Not entered",'Enter Answers'!D28),IF('Enter Answers'!O12="Differs","Different form",IF(LEN('Enter Answers'!D28)>0,"Answer/status conflict",IF(TRUE,"Valid","Invalid value")))) -> Valid | S12: =IF(LEN('Enter Answers'!E12)=0,IF(LEN('Enter Answers'!E28)=0,"Not entered",'Enter Answers'!E28),IF('Enter Answers'!O12="Differs","Different form",IF(LEN('Enter Answers'!E28)>0,"Answer/status conflict",IF(IF(ISNUMBER('Enter Answers'!E12),AND('Enter Answers'!E12>=1,'Enter Answers'!E12<=5,MOD('Enter Answers'!E12,1)=0),FALSE),"Valid","Invalid value")))) -> Valid | T12: =IF(LEN('Enter Answers'!F12)=0,IF(LEN('Enter Answers'!F28)=0,"Not entered",'Enter Answers'!F28),IF('Enter Answers'!O12="Differs","Different form",IF(LEN('Enter Answers'!F28)>0,"Answer/status conflict",IF(IF(ISNUMBER('Enter Answers'!F12),AND('Enter Answers'!F12>=1,'Enter Answers'!F12<=5,MOD('Enter Answers'!F12,1)=0),FALSE),"Valid","Invalid value")))) -> Valid | U12: =IF(LEN('Enter Answers'!G12)=0,IF(LEN('Enter Answers'!G28)=0,"Not entered",'Enter Answers'!G28),IF('Enter Answers'!O12="Differs","Different form",IF(LEN('Enter Answers'!G28)>0,"Answer/status conflict",IF(IF(ISNUMBER('Enter Answers'!G12),AND('Enter Answers'!G12>=1,'Enter Answers'!G12<=5,MOD('Enter Answers'!G12,1)=0),FALSE),"Valid","Invalid value")))) -> Valid | V12: =IF(LEN('Enter Answers'!H12)=0,IF(LEN('Enter Answers'!H28)=0,"Not entered",'Enter Answers'!H28),IF('Enter Answers'!O12="Differs","Different form",IF(LEN('Enter Answers'!H28)>0,"Answer/status conflict",IF(IF(ISNUMBER('Enter Answers'!H12),AND('Enter Answers'!H12>=0,'Enter Answers'!H12<=10,MOD('Enter Answers'!H12,1)=0),FALSE),"Valid","Invalid value")))) -> Valid | W12: =IF(LEN('Enter Answers'!I12)=0,IF(LEN('Enter Answers'!I28)=0,"Not entered",'Enter Answers'!I28),IF('Enter Answers'!O12="Differs","Different form",IF(LEN('Enter Answers'!I28)>0,"Answer/status conflict",IF(IF(ISNUMBER('Enter Answers'!I12),AND('Enter Answers'!I12>=0,'Enter Answers'!I12<=10,MOD('Enter Answers'!I12,1)=0),FALSE),"Valid","Invalid value")))) -> Valid | X12: =IF(LEN('Enter Answers'!J12)=0,IF(LEN('Enter Answers'!J28)=0,"Not entered",'Enter Answers'!J28),IF('Enter Answers'!O12="Differs","Different form",IF(LEN('Enter Answers'!J28)>0,"Answer/status conflict",IF(OR('Enter Answers'!J12="Yes",'Enter Answers'!J12="Undecided",'Enter Answers'!J12="No"),"Valid","Invalid value")))) -> Valid | Y12: =IF(LEN('Enter Answers'!K12)=0,IF(LEN('Enter Answers'!K28)=0,"Not entered",'Enter Answers'!K28),IF('Enter Answers'!O12="Differs","Different form",IF(LEN('Enter Answers'!K28)>0,"Answer/status conflict",IF(OR('Enter Answers'!K12="Willing",'Enter Answers'!K12="Undecided",'Enter Answers'!K12="Unwilling"),"Valid","Invalid value")))) -> Valid | Z12: =IF(LEN('Enter Answers'!L12)=0,IF(LEN('Enter Answers'!L28)=0,"Not entered",'Enter Answers'!L28),IF('Enter Answers'!O12="Differs","Different form",IF(LEN('Enter Answers'!L28)>0,"Answer/status conflict",IF(TRUE,"Valid","Invalid value")))) -> Valid
A13: =IF(LEN('Enter Answers'!A13)=0,"",'Enter Answers'!A13) -> S2-Q007 | B13: =IF(LEN('Enter Answers'!B13)=0,"",'Enter Answers'!B13) -> S2-P017 | C13: =IF(LEN('Enter Answers'!C13)=0,"",'Enter Answers'!C13) -> Resident | D13: =IF(R13="Valid",'Enter Answers'!D13,"") -> 好玩，有用。比以前好玩好多。 | E13: =IF(S13="Valid",'Enter Answers'!E13,"") -> 4 | F13: =IF(T13="Valid",'Enter Answers'!F13,"") -> 4 | G13: =IF(U13="Valid",'Enter Answers'!G13,"") -> 2 | H13: =IF(V13="Valid",'Enter Answers'!H13,"") -> 8 | I13: =IF(W13="Valid",'Enter Answers'!I13,"") -> 8 | J13: =IF(X13="Valid",'Enter Answers'!J13,"") -> Yes | K13: =IF(Y13="Valid",'Enter Answers'!K13,"") -> Willing | L13: =IF(Z13="Valid",'Enter Answers'!L13,"") -> 想分享一下體驗。可以提高集中注意力。唔知其他人點解唔試 | M13: =9-COUNTBLANK('Enter Answers'!D13:L13) -> 9 | N13: =COUNTIFS(R13:Z13,"Invalid value")+COUNTIFS(R13:Z13,"Answer/status conflict")+COUNTIFS(R13:Z13,"Different form") -> 0 | O13: =IF(AND(M13>0,P13<>"Matches"),1,0) -> 1 | P13: =IF(LEN('Enter Answers'!O13)=0,"",'Enter Answers'!O13) -> Not checked | R13: =IF(LEN('Enter Answers'!D13)=0,IF(LEN('Enter Answers'!D29)=0,"Not entered",'Enter Answers'!D29),IF('Enter Answers'!O13="Differs","Different form",IF(LEN('Enter Answers'!D29)>0,"Answer/status conflict",IF(TRUE,"Valid","Invalid value")))) -> Valid | S13: =IF(LEN('Enter Answers'!E13)=0,IF(LEN('Enter Answers'!E29)=0,"Not entered",'Enter Answers'!E29),IF('Enter Answers'!O13="Differs","Different form",IF(LEN('Enter Answers'!E29)>0,"Answer/status conflict",IF(IF(ISNUMBER('Enter Answers'!E13),AND('Enter Answers'!E13>=1,'Enter Answers'!E13<=5,MOD('Enter Answers'!E13,1)=0),FALSE),"Valid","Invalid value")))) -> Valid | T13: =IF(LEN('Enter Answers'!F13)=0,IF(LEN('Enter Answers'!F29)=0,"Not entered",'Enter Answers'!F29),IF('Enter Answers'!O13="Differs","Different form",IF(LEN('Enter Answers'!F29)>0,"Answer/status conflict",IF(IF(ISNUMBER('Enter Answers'!F13),AND('Enter Answers'!F13>=1,'Enter Answers'!F13<=5,MOD('Enter Answers'!F13,1)=0),FALSE),"Valid","Invalid value")))) -> Valid | U13: =IF(LEN('Enter Answers'!G13)=0,IF(LEN('Enter Answers'!G29)=0,"Not entered",'Enter Answers'!G29),IF('Enter Answers'!O13="Differs","Different form",IF(LEN('Enter Answers'!G29)>0,"Answer/status conflict",IF(IF(ISNUMBER('Enter Answers'!G13),AND('Enter Answers'!G13>=1,'Enter Answers'!G13<=5,MOD('Enter Answers'!G13,1)=0),FALSE),"Valid","Invalid value")))) -> Valid | V13: =IF(LEN('Enter Answers'!H13)=0,IF(LEN('Enter Answers'!H29)=0,"Not entered",'Enter Answers'!H29),IF('Enter Answers'!O13="Differs","Different form",IF(LEN('Enter Answers'!H29)>0,"Answer/status conflict",IF(IF(ISNUMBER('Enter Answers'!H13),AND('Enter Answers'!H13>=0,'Enter Answers'!H13<=10,MOD('Enter Answers'!H13,1)=0),FALSE),"Valid","Invalid value")))) -> Valid | W13: =IF(LEN('Enter Answers'!I13)=0,IF(LEN('Enter Answers'!I29)=0,"Not entered",'Enter Answers'!I29),IF('Enter Answers'!O13="Differs","Different form",IF(LEN('Enter Answers'!I29)>0,"Answer/status conflict",IF(IF(ISNUMBER('Enter Answers'!I13),AND('Enter Answers'!I13>=0,'Enter Answers'!I13<=10,MOD('Enter Answers'!I13,1)=0),FALSE),"Valid","Invalid value")))) -> Valid | X13: =IF(LEN('Enter Answers'!J13)=0,IF(LEN('Enter Answers'!J29)=0,"Not entered",'Enter Answers'!J29),IF('Enter Answers'!O13="Differs","Different form",IF(LEN('Enter Answers'!J29)>0,"Answer/status conflict",IF(OR('Enter Answers'!J13="Yes",'Enter Answers'!J13="Undecided",'Enter Answers'!J13="No"),"Valid","Invalid value")))) -> Valid | Y13: =IF(LEN('Enter Answers'!K13)=0,IF(LEN('Enter Answers'!K29)=0,"Not entered",'Enter Answers'!K29),IF('Enter Answers'!O13="Differs","Different form",IF(LEN('Enter Answers'!K29)>0,"Answer/status conflict",IF(OR('Enter Answers'!K13="Willing",'Enter Answers'!K13="Undecided",'Enter Answers'!K13="Unwilling"),"Valid","Invalid value")))) -> Valid | Z13: =IF(LEN('Enter Answers'!L13)=0,IF(LEN('Enter Answers'!L29)=0,"Not entered",'Enter Answers'!L29),IF('Enter Answers'!O13="Differs","Different form",IF(LEN('Enter Answers'!L29)>0,"Answer/status conflict",IF(TRUE,"Valid","Invalid value")))) -> Valid
A14: =IF(LEN('Enter Answers'!A14)=0,"",'Enter Answers'!A14) -> S2-Q008 | B14: =IF(LEN('Enter Answers'!B14)=0,"",'Enter Answers'!B14) -> S2-P030 | C14: =IF(LEN('Enter Answers'!C14)=0,"",'Enter Answers'!C14) -> Resident | D14: =IF(R14="Valid",'Enter Answers'!D14,"") -> 好玩，好似無特別用處。滑來滑去，玩左幾次。有時間可以再玩，不過畫面就幼稚一些。 | E14: =IF(S14="Valid",'Enter Answers'!E14,"") -> 4 | F14: =IF(T14="Valid",'Enter Answers'!F14,"") -> 5 | G14: =IF(U14="Valid",'Enter Answers'!G14,"") -> 2 | H14: =IF(V14="Valid",'Enter Answers'!H14,"") -> 6 | I14: =IF(W14="Valid",'Enter Answers'!I14,"") -> 6 | J14: =IF(X14="Valid",'Enter Answers'!J14,"") -> Yes | K14: =IF(Y14="Valid",'Enter Answers'!K14,"") -> Willing | L14: =IF(Z14="Valid",'Enter Answers'!L14,"") -> 好有用。活動力提高。有遊戲好玩好多， | M14: =9-COUNTBLANK('Enter Answers'!D14:L14) -> 9 | N14: =COUNTIFS(R14:Z14,"Invalid value")+COUNTIFS(R14:Z14,"Answer/status conflict")+COUNTIFS(R14:Z14,"Different form") -> 0 | O14: =IF(AND(M14>0,P14<>"Matches"),1,0) -> 1 | P14: =IF(LEN('Enter Answers'!O14)=0,"",'Enter Answers'!O14) -> Not checked | R14: =IF(LEN('Enter Answers'!D14)=0,IF(LEN('Enter Answers'!D30)=0,"Not entered",'Enter Answers'!D30),IF('Enter Answers'!O14="Differs","Different form",IF(LEN('Enter Answers'!D30)>0,"Answer/status conflict",IF(TRUE,"Valid","Invalid value")))) -> Valid | S14: =IF(LEN('Enter Answers'!E14)=0,IF(LEN('Enter Answers'!E30)=0,"Not entered",'Enter Answers'!E30),IF('Enter Answers'!O14="Differs","Different form",IF(LEN('Enter Answers'!E30)>0,"Answer/status conflict",IF(IF(ISNUMBER('Enter Answers'!E14),AND('Enter Answers'!E14>=1,'Enter Answers'!E14<=5,MOD('Enter Answers'!E14,1)=0),FALSE),"Valid","Invalid value")))) -> Valid | T14: =IF(LEN('Enter Answers'!F14)=0,IF(LEN('Enter Answers'!F30)=0,"Not entered",'Enter Answers'!F30),IF('Enter Answers'!O14="Differs","Different form",IF(LEN('Enter Answers'!F30)>0,"Answer/status conflict",IF(IF(ISNUMBER('Enter Answers'!F14),AND('Enter Answers'!F14>=1,'Enter Answers'!F14<=5,MOD('Enter Answers'!F14,1)=0),FALSE),"Valid","Invalid value")))) -> Valid | U14: =IF(LEN('Enter Answers'!G14)=0,IF(LEN('Enter Answers'!G30)=0,"Not entered",'Enter Answers'!G30),IF('Enter Answers'!O14="Differs","Different form",IF(LEN('Enter Answers'!G30)>0,"Answer/status conflict",IF(IF(ISNUMBER('Enter Answers'!G14),AND('Enter Answers'!G14>=1,'Enter Answers'!G14<=5,MOD('Enter Answers'!G14,1)=0),FALSE),"Valid","Invalid value")))) -> Valid | V14: =IF(LEN('Enter Answers'!H14)=0,IF(LEN('Enter Answers'!H30)=0,"Not entered",'Enter Answers'!H30),IF('Enter Answers'!O14="Differs","Different form",IF(LEN('Enter Answers'!H30)>0,"Answer/status conflict",IF(IF(ISNUMBER('Enter Answers'!H14),AND('Enter Answers'!H14>=0,'Enter Answers'!H14<=10,MOD('Enter Answers'!H14,1)=0),FALSE),"Valid","Invalid value")))) -> Valid | W14: =IF(LEN('Enter Answers'!I14)=0,IF(LEN('Enter Answers'!I30)=0,"Not entered",'Enter Answers'!I30),IF('Enter Answers'!O14="Differs","Different form",IF(LEN('Enter Answers'!I30)>0,"Answer/status conflict",IF(IF(ISNUMBER('Enter Answers'!I14),AND('Enter Answers'!I14>=0,'Enter Answers'!I14<=10,MOD('Enter Answers'!I14,1)=0),FALSE),"Valid","Invalid value")))) -> Valid | X14: =IF(LEN('Enter Answers'!J14)=0,IF(LEN('Enter Answers'!J30)=0,"Not entered",'Enter Answers'!J30),IF('Enter Answers'!O14="Differs","Different form",IF(LEN('Enter Answers'!J30)>0,"Answer/status conflict",IF(OR('Enter Answers'!J14="Yes",'Enter Answers'!J14="Undecided",'Enter Answers'!J14="No"),"Valid","Invalid value")))) -> Valid | Y14: =IF(LEN('Enter Answers'!K14)=0,IF(LEN('Enter Answers'!K30)=0,"Not entered",'Enter Answers'!K30),IF('Enter Answers'!O14="Differs","Different form",IF(LEN('Enter Answers'!K30)>0,"Answer/status conflict",IF(OR('Enter Answers'!K14="Willing",'Enter Answers'!K14="Undecided",'Enter Answers'!K14="Unwilling"),"Valid","Invalid value")))) -> Valid | Z14: =IF(LEN('Enter Answers'!L14)=0,IF(LEN('Enter Answers'!L30)=0,"Not entered",'Enter Answers'!L30),IF('Enter Answers'!O14="Differs","Different form",IF(LEN('Enter Answers'!L30)>0,"Answer/status conflict",IF(TRUE,"Valid","Invalid value")))) -> Valid
A15: =IF(LEN('Enter Answers'!A15)=0,"",'Enter Answers'!A15) -> S2-Q009 | B15: =IF(LEN('Enter Answers'!B15)=0,"",'Enter Answers'!B15) -> S2-P023 | C15: =IF(LEN('Enter Answers'!C15)=0,"",'Enter Answers'!C15) -> Resident | D15: =IF(R15="Valid",'Enter Answers'!D15,"") -> 好玩，有用。玩左好多次。有D挑戰。 | E15: =IF(S15="Valid",'Enter Answers'!E15,"") -> 5 | F15: =IF(T15="Valid",'Enter Answers'!F15,"") -> 5 | G15: =IF(U15="Valid",'Enter Answers'!G15,"") -> 1 | H15: =IF(V15="Valid",'Enter Answers'!H15,"") -> 7 | I15: =IF(W15="Valid",'Enter Answers'!I15,"") -> 7 | J15: =IF(X15="Valid",'Enter Answers'!J15,"") -> Yes | K15: =IF(Y15="Valid",'Enter Answers'!K15,"") -> Willing | L15: =IF(Z15="Valid",'Enter Answers'!L15,"") -> 感覺有D用，無以前咁痛。可以鍛鍊多D | M15: =9-COUNTBLANK('Enter Answers'!D15:L15) -> 9 | N15: =COUNTIFS(R15:Z15,"Invalid value")+COUNTIFS(R15:Z15,"Answer/status conflict")+COUNTIFS(R15:Z15,"Different form") -> 0 | O15: =IF(AND(M15>0,P15<>"Matches"),1,0) -> 1 | P15: =IF(LEN('Enter Answers'!O15)=0,"",'Enter Answers'!O15) -> Not checked | R15: =IF(LEN('Enter Answers'!D15)=0,IF(LEN('Enter Answers'!D31)=0,"Not entered",'Enter Answers'!D31),IF('Enter Answers'!O15="Differs","Different form",IF(LEN('Enter Answers'!D31)>0,"Answer/status conflict",IF(TRUE,"Valid","Invalid value")))) -> Valid | S15: =IF(LEN('Enter Answers'!E15)=0,IF(LEN('Enter Answers'!E31)=0,"Not entered",'Enter Answers'!E31),IF('Enter Answers'!O15="Differs","Different form",IF(LEN('Enter Answers'!E31)>0,"Answer/status conflict",IF(IF(ISNUMBER('Enter Answers'!E15),AND('Enter Answers'!E15>=1,'Enter Answers'!E15<=5,MOD('Enter Answers'!E15,1)=0),FALSE),"Valid","Invalid value")))) -> Valid | T15: =IF(LEN('Enter Answers'!F15)=0,IF(LEN('Enter Answers'!F31)=0,"Not entered",'Enter Answers'!F31),IF('Enter Answers'!O15="Differs","Different form",IF(LEN('Enter Answers'!F31)>0,"Answer/status conflict",IF(IF(ISNUMBER('Enter Answers'!F15),AND('Enter Answers'!F15>=1,'Enter Answers'!F15<=5,MOD('Enter Answers'!F15,1)=0),FALSE),"Valid","Invalid value")))) -> Valid | U15: =IF(LEN('Enter Answers'!G15)=0,IF(LEN('Enter Answers'!G31)=0,"Not entered",'Enter Answers'!G31),IF('Enter Answers'!O15="Differs","Different form",IF(LEN('Enter Answers'!G31)>0,"Answer/status conflict",IF(IF(ISNUMBER('Enter Answers'!G15),AND('Enter Answers'!G15>=1,'Enter Answers'!G15<=5,MOD('Enter Answers'!G15,1)=0),FALSE),"Valid","Invalid value")))) -> Valid | V15: =IF(LEN('Enter Answers'!H15)=0,IF(LEN('Enter Answers'!H31)=0,"Not entered",'Enter Answers'!H31),IF('Enter Answers'!O15="Differs","Different form",IF(LEN('Enter Answers'!H31)>0,"Answer/status conflict",IF(IF(ISNUMBER('Enter Answers'!H15),AND('Enter Answers'!H15>=0,'Enter Answers'!H15<=10,MOD('Enter Answers'!H15,1)=0),FALSE),"Valid","Invalid value")))) -> Valid | W15: =IF(LEN('Enter Answers'!I15)=0,IF(LEN('Enter Answers'!I31)=0,"Not entered",'Enter Answers'!I31),IF('Enter Answers'!O15="Differs","Different form",IF(LEN('Enter Answers'!I31)>0,"Answer/status conflict",IF(IF(ISNUMBER('Enter Answers'!I15),AND('Enter Answers'!I15>=0,'Enter Answers'!I15<=10,MOD('Enter Answers'!I15,1)=0),FALSE),"Valid","Invalid value")))) -> Valid | X15: =IF(LEN('Enter Answers'!J15)=0,IF(LEN('Enter Answers'!J31)=0,"Not entered",'Enter Answers'!J31),IF('Enter Answers'!O15="Differs","Different form",IF(LEN('Enter Answers'!J31)>0,"Answer/status conflict",IF(OR('Enter Answers'!J15="Yes",'Enter Answers'!J15="Undecided",'Enter Answers'!J15="No"),"Valid","Invalid value")))) -> Valid | Y15: =IF(LEN('Enter Answers'!K15)=0,IF(LEN('Enter Answers'!K31)=0,"Not entered",'Enter Answers'!K31),IF('Enter Answers'!O15="Differs","Different form",IF(LEN('Enter Answers'!K31)>0,"Answer/status conflict",IF(OR('Enter Answers'!K15="Willing",'Enter Answers'!K15="Undecided",'Enter Answers'!K15="Unwilling"),"Valid","Invalid value")))) -> Valid | Z15: =IF(LEN('Enter Answers'!L15)=0,IF(LEN('Enter Answers'!L31)=0,"Not entered",'Enter Answers'!L31),IF('Enter Answers'!O15="Differs","Different form",IF(LEN('Enter Answers'!L31)>0,"Answer/status conflict",IF(TRUE,"Valid","Invalid value")))) -> Valid

Sheet Stage 2 ID Key
A2: Established Stage 2 player IDs
A3: 30 residents and two controls. These are the established player codes, separate from the nine questionnaire-record codes.
A6: Stage 2 player ID | B6: Record type | C6: Original FRA row | D6: Gender | E6: Age in years
A7: S2-P001 | B7: Resident | C7: 3 | D7: M | E7: 63
A8: S2-C001 | B8: Control | C8: 4 | D8: M | E8: 36
A9: S2-P002 | B9: Resident | C9: 5 | D9: M | E9: 62
A10: S2-P003 | B10: Resident | C10: 6 | D10: M | E10: 66
A11: S2-P004 | B11: Resident | C11: 7 | D11: M | E11: 65
A12: S2-P005 | B12: Resident | C12: 8 | D12: M | E12: 64
A13: S2-P006 | B13: Resident | C13: 9 | D13: M | E13: 70
A14: S2-P007 | B14: Resident | C14: 10 | D14: M | E14: 72
A15: S2-P008 | B15: Resident | C15: 11 | D15: M | E15: 76
A16: S2-P009 | B16: Resident | C16: 12 | D16: M | E16: 74
A17: S2-P010 | B17: Resident | C17: 13 | D17: M | E17: 69
A18: S2-P011 | B18: Resident | C18: 14 | D18: M | E18: 71
... A38: S2-P030 | B38: Resident | C38: 34 | D38: F | E38: 84
A41: Source: Reference 3 in Question Guide. Keep these IDs fixed when records are sorted.
