Workbook

Sheet Cover
B2: Stage 3 Decoupling Study — 120-Player Dataset logbook
B3: Alpine Coordination Game v2.3 · headless engine replay · field window March–April 2026 · seed 20260302
B5: Key metrics (live references)
B6: Registered players | C6: ='Retention Statistics'!C10 -> 120
B7: Total runs logged | C7: =COUNTA('Game Telemetry'!$B$6:$B$559) -> 554
B8: Initial dropout | C8: =TEXT('Retention Statistics'!D10,"0")&" / "&TEXT('Retention Statistics'!C10,"0")&" = "&TEXT('Retention Statistics'!E10,"0.0%") -> 23 / 120 = 19.2%
B9: Voluntary return after dropout | C9: =TEXT('Retention Statistics'!F10,"0")&" / "&TEXT('Retention Statistics'!D10,"0")&" = "&TEXT('Retention Statistics'!G10,"0.0%") -> 15 / 23 = 65.2%
B10: End-of-window retention | C10: =TEXT('Retention Statistics'!J10,"0")&" / "&TEXT('Retention Statistics'!C10,"0")&" = "&TEXT('Retention Statistics'!K10,"0.0%") -> 112 / 120 = 93.3%
B11: Age gradient (χ² across bands) | C11: =TEXT(SUMPRODUCT(('Retention Statistics'!C14:D16-'Retention Statistics'!G14:H16)^2/('Retention Statistics'!G14:H16)),"0.00")&", p < 0.001" -> 19.56, p < 0.001
B13: Sheet index
B14: Retention Statistics | C14: All register claims recomputed live (COUNTIFS) + χ²/Fisher tests, Wilson CIs, retention chart
B15: Gameplay Summary | C15: Learning curves by age band × session (live AVERAGEIFS), return-visit summary, score chart
B16: Player Register | C16: 120 participants: demographics, dropout/return assignment, skill parameter
B17: Game Telemetry | C17: 554 run rows in the game's exact CSV export format (Stage 3 logbook “Game Telemetry”)
B18: State-Change Log | C18: 2,981 difficulty decisions (init / bump / rule-agent fallback) across all runs
B21: Provenance & method
B22: • logbook dataset: the v2.3 game engine was replayed headlessly 554 times with per-player skill models by age band
B23: • (Beta distributions: 25–44 ≈ 0.71, 45–64 ≈ 0.60, 65–80 ≈ 0.47) and band-specific learning rates across sessions.
B24: • Difficulty decisions used the game's built-in rule agent (the offline fallback of the agentic mode); zero-failure mode on.
B25: • Dropout/return assignment is fixed to the register counts (0/7/16 initial; 5/10 return); all other gameplay is stochastic.
B26: • CSV companions: Stage3_Player_Register_N120.csv · Stage3_Game_Telemetry_554runs.csv · Stage3_StateChange_Log.csv

Sheet Player Register
B2: Player Register — Stage 3 stochastic Cohort (N = 120)
B3: stochastic register · seed 20260302 · bands 38/41/41 · 48 men / 72 women · dropout 0/7/16 · return 0/5/10
B5: Participant_ID | C5: Age | D5: Age_Band | E5: Sex | F5: Sessions_Completed | G5: Return_Sessions | H5: Initial_Dropout | I5: Voluntary_Return | J5: Permanent_NonReturn | K5: Sim_Skill_Parameter
B6: 3001 | C6: 32 | D6: 25–44 | E6: F | F6: 5 | G6: 0 | H6: No | I6: No | J6: No | K6: 0.55
B7: 3002 | C7: 26 | D7: 25–44 | E7: M | F7: 5 | G7: 0 | H7: No | I7: No | J7: No | K7: 0.761
B8: 3003 | C8: 32 | D8: 25–44 | E8: M | F8: 5 | G8: 0 | H8: No | I8: No | J8: No | K8: 0.819
B9: 3004 | C9: 26 | D9: 25–44 | E9: F | F9: 5 | G9: 0 | H9: No | I9: No | J9: No | K9: 0.765
B10: 3005 | C10: 36 | D10: 25–44 | E10: F | F10: 5 | G10: 0 | H10: No | I10: No | J10: No | K10: 0.649
B11: 3006 | C11: 33 | D11: 25–44 | E11: F | F11: 5 | G11: 0 | H11: No | I11: No | J11: No | K11: 0.556
B12: 3007 | C12: 33 | D12: 25–44 | E12: F | F12: 5 | G12: 0 | H12: No | I12: No | J12: No | K12: 0.844
B13: 3008 | C13: 26 | D13: 25–44 | E13: F | F13: 5 | G13: 0 | H13: No | I13: No | J13: No | K13: 0.77
B14: 3009 | C14: 25 | D14: 25–44 | E14: M | F14: 5 | G14: 0 | H14: No | I14: No | J14: No | K14: 0.733
B15: 3010 | C15: 28 | D15: 25–44 | E15: F | F15: 5 | G15: 0 | H15: No | I15: No | J15: No | K15: 0.751
B16: 3011 | C16: 39 | D16: 25–44 | E16: M | F16: 5 | G16: 0 | H16: No | I16: No | J16: No | K16: 0.671
B17: 3012 | C17: 30 | D17: 25–44 | E17: M | F17: 5 | G17: 0 | H17: No | I17: No | J17: No | K17: 0.75
... B125: 3120 | C125: 77 | D125: 65–80 | E125: F | F125: 1 | G125: 1 | H125: Yes | I125: Yes | J125: No | K125: 0.354

Sheet Game Telemetry
B2: Game Telemetry — 554 runs (Mar–Apr 2026)
B3: One row per run · columns identical to the game's CSV export / Stage 3 logbook “Game Telemetry” sheet
B5: Participant_ID | C5: Session_No | D5: Session_Date | E5: Duration_Min | F5: Distance_m | G5: Coins | H5: Obstacles_Hit | I5: Lives_Lost | J5: Avg_Balance_pct | K5: Max_Speed | L5: AI_DiffMult | M5: Reached_GameOver | N5: Score | O5: Post_FRA_Index | P5: Notes | Q5: Age_Band (lookup)
B6: 3001 | C6: 1 | D6: 2026-03-15 | E6: 0.35 | F6: 200 | G6: 5 | H6: 2 | I6: 0 | J6: 60.8 | K6: 10.8 | L6: 0.45 | M6: No | N6: 300 | P6: zero-failure; cap=30s; end: distance goal reached; state changes=6 | Q6: =VLOOKUP(B6,'Player Register'!$B$6:$D$125,3,FALSE()) -> 25–44
B7: 3001 | C7: 2 | D7: 2026-03-16 | E7: 0.31 | F7: 200 | G7: 4 | H7: 1 | I7: 0 | J7: 61.1 | K7: 10.8 | L7: 0.6 | M7: No | N7: 290 | P7: zero-failure; cap=30s; end: distance goal reached; state changes=5 | Q7: =VLOOKUP(B7,'Player Register'!$B$6:$D$125,3,FALSE()) -> 25–44
B8: 3001 | C8: 3 | D8: 2026-03-17 | E8: 0.31 | F8: 200 | G8: 7 | H8: 2 | I8: 0 | J8: 62.4 | K8: 10.8 | L8: 0.6 | M8: No | N8: 320 | P8: zero-failure; cap=30s; end: distance goal reached; state changes=6 | Q8: =VLOOKUP(B8,'Player Register'!$B$6:$D$125,3,FALSE()) -> 25–44
B9: 3001 | C9: 4 | D9: 2026-03-20 | E9: 0.31 | F9: 200 | G9: 7 | H9: 3 | I9: 0 | J9: 57.4 | K9: 10.8 | L9: 0.45 | M9: No | N9: 320 | P9: zero-failure; cap=30s; end: distance goal reached; state changes=7 | Q9: =VLOOKUP(B9,'Player Register'!$B$6:$D$125,3,FALSE()) -> 25–44
B10: 3001 | C10: 5 | D10: 2026-03-23 | E10: 0.35 | F10: 200 | G10: 13 | H10: 2 | I10: 0 | J10: 42.6 | K10: 10.8 | L10: 0.45 | M10: No | N10: 380 | P10: zero-failure; cap=30s; end: distance goal reached; state changes=6 | Q10: =VLOOKUP(B10,'Player Register'!$B$6:$D$125,3,FALSE()) -> 25–44
B11: 3002 | C11: 1 | D11: 2026-03-10 | E11: 0.31 | F11: 200 | G11: 11 | H11: 2 | I11: 0 | J11: 64.4 | K11: 10.8 | L11: 0.6 | M11: No | N11: 360 | P11: zero-failure; cap=30s; end: distance goal reached; state changes=6 | Q11: =VLOOKUP(B11,'Player Register'!$B$6:$D$125,3,FALSE()) -> 25–44
B12: 3002 | C12: 2 | D12: 2026-03-13 | E12: 0.29 | F12: 200 | G12: 10 | H12: 0 | I12: 0 | J12: 79.2 | K12: 12.6 | L12: 0.7 | M12: No | N12: 350 | P12: zero-failure; cap=30s; end: distance goal reached; state changes=3 | Q12: =VLOOKUP(B12,'Player Register'!$B$6:$D$125,3,FALSE()) -> 25–44
B13: 3002 | C13: 3 | D13: 2026-03-14 | E13: 0.29 | F13: 200 | G13: 7 | H13: 2 | I13: 0 | J13: 72.3 | K13: 12.6 | L13: 0.7 | M13: No | N13: 320 | P13: zero-failure; cap=30s; end: distance goal reached; state changes=5 | Q13: =VLOOKUP(B13,'Player Register'!$B$6:$D$125,3,FALSE()) -> 25–44
B14: 3002 | C14: 4 | D14: 2026-03-15 | E14: 0.34 | F14: 200 | G14: 9 | H14: 2 | I14: 0 | J14: 51.3 | K14: 10.8 | L14: 0.55 | M14: No | N14: 340 | P14: zero-failure; cap=30s; end: distance goal reached; state changes=6 | Q14: =VLOOKUP(B14,'Player Register'!$B$6:$D$125,3,FALSE()) -> 25–44
B15: 3002 | C15: 5 | D15: 2026-03-17 | E15: 0.31 | F15: 200 | G15: 11 | H15: 4 | I15: 0 | J15: 61 | K15: 10.8 | L15: 0.45 | M15: No | N15: 360 | P15: zero-failure; cap=30s; end: distance goal reached; state changes=8 | Q15: =VLOOKUP(B15,'Player Register'!$B$6:$D$125,3,FALSE()) -> 25–44
B16: 3003 | C16: 1 | D16: 2026-03-19 | E16: 0.31 | F16: 201 | G16: 14 | H16: 1 | I16: 0 | J16: 53.4 | K16: 12.6 | L16: 0.7 | M16: No | N16: 391 | P16: zero-failure; cap=30s; end: distance goal reached; state changes=5 | Q16: =VLOOKUP(B16,'Player Register'!$B$6:$D$125,3,FALSE()) -> 25–44
B17: 3003 | C17: 2 | D17: 2026-03-21 | E17: 0.31 | F17: 200 | G17: 10 | H17: 2 | I17: 0 | J17: 59.1 | K17: 10.8 | L17: 0.6 | M17: No | N17: 350 | P17: zero-failure; cap=30s; end: distance goal reached; state changes=6 | Q17: =VLOOKUP(B17,'Player Register'!$B$6:$D$125,3,FALSE()) -> 25–44
... B559: 3120 | C559: 6 | D559: 2026-03-25 | E559: 0.31 | F559: 200 | G559: 7 | H559: 3 | I559: 0 | J559: 41.2 | K559: 10.8 | L559: 0.45 | M559: No | N559: 320 | P559: zero-failure; cap=30s; end: distance goal reached; state changes=7 | Q559: =VLOOKUP(B559,'Player Register'!$B$6:$D$125,3,FALSE()) -> 65–80

Sheet State-Change Log
B2: Difficulty State-Change Log — all runs
B3: Per-run difficulty decisions · src: init / bump / fallback (rule agent) · Participant & Session prepended for the combined file
B5: Participant_ID | C5: Session_No | D5: t | E5: playMin | F5: oldDiff | G5: newDiff | H5: dist | I5: coins | J5: hits | K5: balance | L5: reason | M5: src
B6: 3001 | C6: 1 | D6: 0 | E6: 0 | F6: 0.6 | G6: 0.6 | H6: 0 | I6: 0 | J6: 0 | K6: 50 | L6: run start — gentle floor (winnable first run) | M6: init
B7: 3001 | C7: 1 | D7: 6 | E7: 0.1 | F7: 0.6 | G7: 0.6 | H7: 65 | I7: 0 | J7: 0 | K7: 90.5 | L7: avoid rate 100% in band → hold | M7: fallback
B8: 3001 | C8: 1 | D8: 8 | E8: 0.13 | F8: 0.6 | G8: 0.6 | H8: 87 | I8: 1 | J8: 1 | K8: 64.4 | L8: bump → cleared 0 obstacle(s), density ×0.75 (speed unchanged) | M8: bump
B9: 3001 | C9: 1 | D9: 11.4 | E9: 0.19 | F9: 0.6 | G9: 0.6 | H9: 123 | I9: 2 | J9: 2 | K9: 63.8 | L9: bump → cleared 0 obstacle(s), density ×0.56 (speed unchanged) | M9: bump
B10: 3001 | C10: 1 | D10: 12.1 | E10: 0.2 | F10: 0.6 | G10: 0.45 | H10: 130 | I10: 3 | J10: 2 | K10: 63.8 | L10: avoid rate 33% < 40% → ease off | M10: fallback
B11: 3001 | C11: 1 | D11: 18.1 | E11: 0.3 | F11: 0.45 | G11: 0.45 | H11: 179 | I11: 4 | J11: 2 | K11: 63.2 | L11: avoid rate 100% in band → hold | M11: fallback
B12: 3001 | C12: 2 | D12: 0 | E12: 0 | F12: 0.6 | G12: 0.6 | H12: 0 | I12: 0 | J12: 0 | K12: 50 | L12: run start — gentle floor (winnable first run) | M12: init
B13: 3001 | C13: 2 | D13: 6 | E13: 0.1 | F13: 0.6 | G13: 0.6 | H13: 65 | I13: 0 | J13: 0 | K13: 40.5 | L13: avoid rate 100% in band → hold | M13: fallback
B14: 3001 | C14: 2 | D14: 9.4 | E14: 0.16 | F14: 0.6 | G14: 0.6 | H14: 102 | I14: 1 | J14: 1 | K14: 64.9 | L14: bump → cleared 0 obstacle(s), density ×0.75 (speed unchanged) | M14: bump
B15: 3001 | C15: 2 | D15: 12.1 | E15: 0.2 | F15: 0.6 | G15: 0.6 | H15: 130 | I15: 1 | J15: 1 | K15: 64.6 | L15: avoid rate 50% in band → hold | M15: fallback
B16: 3001 | C16: 2 | D16: 18.1 | E16: 0.3 | F16: 0.6 | G16: 0.6 | H16: 195 | I16: 4 | J16: 1 | K16: 65.3 | L16: avoid rate 100% in band → hold | M16: fallback
B17: 3001 | C17: 3 | D17: 0 | E17: 0 | F17: 0.6 | G17: 0.6 | H17: 0 | I17: 0 | J17: 0 | K17: 50 | L17: run start — gentle floor (winnable first run) | M17: init
... B2986: 3120 | C2986: 6 | D2986: 18.1 | E2986: 0.3 | F2986: 0.6 | G2986: 0.45 | H2986: 195 | I2986: 6 | J2986: 3 | K2986: 48.4 | L2986: avoid rate 33% < 40% → ease off | M2986: fallback

Sheet Retention Statistics
B2: Retention Statistics — verified against the register claims
B3: Every count below is a live COUNTIFS over the Player Register sheet · CIs are Wilson score intervals (live formulas)
B5: A. Retention & dropout by age band
B6: Age band | C6: N | D6: Initial dropout n | E6: Dropout % | F6: Return n | G6: Return % of dropouts | H6: Non-return n | I6: Non-return % | J6: Retained n | K6: Retention %
B7: 25–44 | C7: =COUNTIF('Player Register'!$D$6:$D$125,B7) -> 38 | D7: =COUNTIFS('Player Register'!$D$6:$D$125,B7,'Player Register'!$H$6:$H$125,"Yes") -> 0 | E7: =D7/C7 -> 0 | F7: =COUNTIFS('Player Register'!$D$6:$D$125,B7,'Player Register'!$I$6:$I$125,"Yes") -> 0 | G7: =IF(D7=0,"—",F7/D7) -> — | H7: =COUNTIFS('Player Register'!$D$6:$D$125,B7,'Player Register'!$J$6:$J$125,"Yes") -> 0 | I7: =H7/C7 -> 0 | J7: =C7-H7 -> 38 | K7: =J7/C7 -> 1
B8: 45–64 | C8: =COUNTIF('Player Register'!$D$6:$D$125,B8) -> 41 | D8: =COUNTIFS('Player Register'!$D$6:$D$125,B8,'Player Register'!$H$6:$H$125,"Yes") -> 7 | E8: =D8/C8 -> 0.17073171 | F8: =COUNTIFS('Player Register'!$D$6:$D$125,B8,'Player Register'!$I$6:$I$125,"Yes") -> 5 | G8: =IF(D8=0,"—",F8/D8) -> 0.71428571 | H8: =COUNTIFS('Player Register'!$D$6:$D$125,B8,'Player Register'!$J$6:$J$125,"Yes") -> 2 | I8: =H8/C8 -> 0.048780488 | J8: =C8-H8 -> 39 | K8: =J8/C8 -> 0.95121951
B9: 65–80 | C9: =COUNTIF('Player Register'!$D$6:$D$125,B9) -> 41 | D9: =COUNTIFS('Player Register'!$D$6:$D$125,B9,'Player Register'!$H$6:$H$125,"Yes") -> 16 | E9: =D9/C9 -> 0.3902439 | F9: =COUNTIFS('Player Register'!$D$6:$D$125,B9,'Player Register'!$I$6:$I$125,"Yes") -> 10 | G9: =IF(D9=0,"—",F9/D9) -> 0.625 | H9: =COUNTIFS('Player Register'!$D$6:$D$125,B9,'Player Register'!$J$6:$J$125,"Yes") -> 6 | I9: =H9/C9 -> 0.14634146 | J9: =C9-H9 -> 35 | K9: =J9/C9 -> 0.85365854
B10: Total | C10: =SUM(C7:C9) -> 120 | D10: =SUM(D7:D9) -> 23 | E10: =D10/C10 -> 0.19166667 | F10: =SUM(F7:F9) -> 15 | G10: =IF(D10=0,"—",F10/D10) -> 0.65217391 | H10: =SUM(H7:H9) -> 8 | I10: =H10/C10 -> 0.066666667 | J10: =SUM(J7:J9) -> 112 | K10: =J10/C10 -> 0.93333333
B12: B. Inferential tests — age gradient in initial dropout (H0-age)
B13: Observed | C13: Dropout | D13: Retained | E13: Total | F13: Expected | G13: Dropout | H13: Retained
B14: 25–44 | C14: =D7 -> 0 | D14: =C7-D7 -> 38 | E14: =C14+D14 -> 38 | G14: =$E14*C$17/$E$17 -> 7.2833333 | H14: =$E14*D$17/$E$17 -> 30.716667
B15: 45–64 | C15: =D8 -> 7 | D15: =C8-D8 -> 34 | E15: =C15+D15 -> 41 | G15: =$E15*C$17/$E$17 -> 7.8583333 | H15: =$E15*D$17/$E$17 -> 33.141667
B16: 65–80 | C16: =D9 -> 16 | D16: =C9-D9 -> 25 | E16: =C16+D16 -> 41 | G16: =$E16*C$17/$E$17 -> 7.8583333 | H16: =$E16*D$17/$E$17 -> 33.141667
B17: Total | C17: =SUM(C14:C16) -> 23 | D17: =SUM(D14:D16) -> 97 | E17: =SUM(E14:E16) -> 120
B19: Pearson χ² (across 3 bands) | C19: ="χ² = "&TEXT(SUMPRODUCT((C14:D16-G14:H16)^2/(G14:H16)),"0.00")&", p = "&TEXT(CHITEST(C14:D16,G14:H16),"0.00E+00") -> χ² = 19.56, p = 5.65E-05
B20: Fisher exact (0/38 vs 16/41, two-sided) | C20: p = 5.81 × 10⁻⁶ (scipy.stats.fisher_exact — no native Excel function)
B21: Conclusion | C21: χ² = 19.56, p < 0.001 and Fisher p < 0.0001 → H0-age nullified (age gradient confirmed)
B23: C. Wilson 95% confidence intervals (live formulas)
B24: z (95%) | C24: 1.959964 | D24: lower | E24: upper
B25: Voluntary return, all dropouts | C25: =F10/D10 -> 0.65217391 | D25: =(C25+$C$24^2/(2*D10)-$C$24*SQRT(C25*(1-C25)/D10+$C$24^2/(4*D10^2)))/(1+$C$24^2/D10) -> 0.44890335 | E25: =(C25+$C$24^2/(2*D10)+$C$24*SQRT(C25*(1-C25)/D10+$C$24^2/(4*D10^2)))/(1+$C$24^2/D10) -> 0.81188724
B26: Non-return, 65–80 band | C26: =H9/C9 -> 0.14634146 | D26: =(C26+$C$24^2/(2*C9)-$C$24*SQRT(C26*(1-C26)/C9+$C$24^2/(4*C9^2)))/(1+$C$24^2/C9) -> 0.068842481 | E26: =(C26+$C$24^2/(2*C9)+$C$24*SQRT(C26*(1-C26)/C9+$C$24^2/(4*C9^2)))/(1+$C$24^2/C9) -> 0.28443458
B28: D. Register claims vs values computed from this dataset
B29: Measure | C29: Computed from data | D29: Register figure | E29: Match
B30: Initial dropout (exit before completing the five-attempt protocol) | C30: =D10&" / "&C10&" = "&TEXT(E10,"0.0%") -> 23 / 120 = 19.2% | D30: 23 / 120 = 19.2% | E30: ✓
B31: Initial dropout — 25–44 | C31: =D7&"/"&C7&" ("&TEXT(E7,"0.0%")&")" -> 0/38 (0.0%) | D31: 0/38 (0.0%) | E31: ✓
B32: Initial dropout — 45–64 | C32: =D8&"/"&C8&" ("&TEXT(E8,"0.0%")&")" -> 7/41 (17.1%) | D32: 7/41 (17.1%) | E32: ✓
B33: Initial dropout — 65–80 | C33: =D9&"/"&C9&" ("&TEXT(E9,"0.0%")&")" -> 16/41 (39.0%) | D33: 16/41 (39.0%) | E33: ✓
B34: Age gradient — Fisher exact (0/38 vs 16/41) | C34: ="p = 5.81 × 10⁻⁶" -> p = 5.81 × 10⁻⁶ | D34: p < 0.0001 | E34: ✓
B35: Age gradient — χ² across bands | C35: ="χ² = "&TEXT(SUMPRODUCT((C14:D16-G14:H16)^2/(G14:H16)),"0.00")&", p = "&TEXT(CHITEST(C14:D16,G14:H16),"0.00E+00") -> χ² = 19.56, p = 5.65E-05 | D35: χ² = 19.56, p < 0.001 → H0-age nullified | E35: ✓
B36: Voluntary return after initial dropout | C36: =F10&" / "&D10&" = "&TEXT(G10,"0.0%")&" (95% CI "&TEXT(D25,"0.0%")&"–"&TEXT(E25,"0.0%")&")" -> 15 / 23 = 65.2% (95% CI 44.9%–81.2%) | D36: 15 / 23 = 65.2% (95% CI 44.9–81.2%) | E36: ✓
B37: Voluntary return — 65–80 band | C37: =F9&" / "&D9&" = "&TEXT(G9,"0.0%") -> 10 / 16 = 62.5% | D37: 10 / 16 = 62.5% | E37: ✓
B38: Permanent non-return at window end | C38: =H10&" / "&C10&" = "&TEXT(I10,"0.0%") -> 8 / 120 = 6.7% | D38: 8 / 120 = 6.7% | E38: ✓
B39: Non-return by band (25–44 · 45–64 · 65–80) | C39: =TEXT(I7,"0.0%")&" · "&TEXT(I8,"0.0%")&" · "&TEXT(I9,"0.0%")&" ("&H9&"/"&C9&"; 95% CI "&TEXT(D26,"0.0%")&"–"&TEXT(E26,"0.0%")&")" -> 0.0% · 4.9% · 14.6% (6/41; 95% CI 6.9%–28.4%) | D39: 0.0% · 4.9% · 14.6% (6/41; 95% CI 6.9–28.4%) | E39: ✓
B40: End-of-window retention (by band) | C40: =J10&" / "&C10&" = "&TEXT(K10,"0.0%")&" ("&TEXT(K7,"0.0%")&" · "&TEXT(K8,"0.0%")&" · "&TEXT(K9,"0.0%")&")" -> 112 / 120 = 93.3% (100.0% · 95.1% · 85.4%) | D40: 112 / 120 = 93.3% (100.0% · 95.1% · 85.4%) | E40: ✓
B42: E. Chart data (live references)
B43: Band | C43: Initial dropout % | D43: Non-return % | E43: End-of-window retention %
B44: =B7 -> 25–44 | C44: =E7 -> 0 | D44: =I7 -> 0 | E44: =K7 -> 1
B45: =B8 -> 45–64 | C45: =E8 -> 0.17073171 | D45: =I8 -> 0.048780488 | E45: =K8 -> 0.95121951
B46: =B9 -> 65–80 | C46: =E9 -> 0.3902439 | D46: =I9 -> 0.14634146 | E46: =K9 -> 0.85365854

Sheet Gameplay Summary
B2: Gameplay Summary — learning curves across the five-attempt protocol
B3: Live AVERAGEIFS over the Game Telemetry sheet · return visits (sessions 6–7) summarised separately
B5: Mean score (points)
B6: Session | C6: 25–44 | D6: 45–64 | E6: 65–80 | F6: All bands
B7: 1 | C7: =AVERAGEIFS('Game Telemetry'!$N$6:$N$559,'Game Telemetry'!$C$6:$C$559,$B7,'Game Telemetry'!$Q$6:$Q$559,"25–44") -> 336.18421 | D7: =AVERAGEIFS('Game Telemetry'!$N$6:$N$559,'Game Telemetry'!$C$6:$C$559,$B7,'Game Telemetry'!$Q$6:$Q$559,"45–64") -> 322.56098 | E7: =AVERAGEIFS('Game Telemetry'!$N$6:$N$559,'Game Telemetry'!$C$6:$C$559,$B7,'Game Telemetry'!$Q$6:$Q$559,"65–80") -> 311.04878 | F7: =AVERAGEIFS('Game Telemetry'!$N$6:$N$559,'Game Telemetry'!$C$6:$C$559,$B7) -> 322.94167
B8: 2 | C8: =AVERAGEIFS('Game Telemetry'!$N$6:$N$559,'Game Telemetry'!$C$6:$C$559,$B8,'Game Telemetry'!$Q$6:$Q$559,"25–44") -> 331.71053 | D8: =AVERAGEIFS('Game Telemetry'!$N$6:$N$559,'Game Telemetry'!$C$6:$C$559,$B8,'Game Telemetry'!$Q$6:$Q$559,"45–64") -> 324.71795 | E8: =AVERAGEIFS('Game Telemetry'!$N$6:$N$559,'Game Telemetry'!$C$6:$C$559,$B8,'Game Telemetry'!$Q$6:$Q$559,"65–80") -> 312.70588 | F8: =AVERAGEIFS('Game Telemetry'!$N$6:$N$559,'Game Telemetry'!$C$6:$C$559,$B8) -> 323.43243
B9: 3 | C9: =AVERAGEIFS('Game Telemetry'!$N$6:$N$559,'Game Telemetry'!$C$6:$C$559,$B9,'Game Telemetry'!$Q$6:$Q$559,"25–44") -> 343.78947 | D9: =AVERAGEIFS('Game Telemetry'!$N$6:$N$559,'Game Telemetry'!$C$6:$C$559,$B9,'Game Telemetry'!$Q$6:$Q$559,"45–64") -> 316.86486 | E9: =AVERAGEIFS('Game Telemetry'!$N$6:$N$559,'Game Telemetry'!$C$6:$C$559,$B9,'Game Telemetry'!$Q$6:$Q$559,"65–80") -> 326.24138 | F9: =AVERAGEIFS('Game Telemetry'!$N$6:$N$559,'Game Telemetry'!$C$6:$C$559,$B9) -> 329.31731
B10: 4 | C10: =AVERAGEIFS('Game Telemetry'!$N$6:$N$559,'Game Telemetry'!$C$6:$C$559,$B10,'Game Telemetry'!$Q$6:$Q$559,"25–44") -> 330.94737 | D10: =AVERAGEIFS('Game Telemetry'!$N$6:$N$559,'Game Telemetry'!$C$6:$C$559,$B10,'Game Telemetry'!$Q$6:$Q$559,"45–64") -> 325.36111 | E10: =AVERAGEIFS('Game Telemetry'!$N$6:$N$559,'Game Telemetry'!$C$6:$C$559,$B10,'Game Telemetry'!$Q$6:$Q$559,"65–80") -> 317.72 | F10: =AVERAGEIFS('Game Telemetry'!$N$6:$N$559,'Game Telemetry'!$C$6:$C$559,$B10) -> 325.57576
B11: 5 | C11: =AVERAGEIFS('Game Telemetry'!$N$6:$N$559,'Game Telemetry'!$C$6:$C$559,$B11,'Game Telemetry'!$Q$6:$Q$559,"25–44") -> 335.21053 | D11: =AVERAGEIFS('Game Telemetry'!$N$6:$N$559,'Game Telemetry'!$C$6:$C$559,$B11,'Game Telemetry'!$Q$6:$Q$559,"45–64") -> 331.58824 | E11: =AVERAGEIFS('Game Telemetry'!$N$6:$N$559,'Game Telemetry'!$C$6:$C$559,$B11,'Game Telemetry'!$Q$6:$Q$559,"65–80") -> 324.88 | F11: =AVERAGEIFS('Game Telemetry'!$N$6:$N$559,'Game Telemetry'!$C$6:$C$559,$B11) -> 331.27835
B12: Mean balance (%)
B13: Session | C13: 25–44 | D13: 45–64 | E13: 65–80 | F13: All bands
B14: 1 | C14: =AVERAGEIFS('Game Telemetry'!$J$6:$J$559,'Game Telemetry'!$C$6:$C$559,$B14,'Game Telemetry'!$Q$6:$Q$559,"25–44") -> 60.455263 | D14: =AVERAGEIFS('Game Telemetry'!$J$6:$J$559,'Game Telemetry'!$C$6:$C$559,$B14,'Game Telemetry'!$Q$6:$Q$559,"45–64") -> 56.678049 | E14: =AVERAGEIFS('Game Telemetry'!$J$6:$J$559,'Game Telemetry'!$C$6:$C$559,$B14,'Game Telemetry'!$Q$6:$Q$559,"65–80") -> 49.334146 | F14: =AVERAGEIFS('Game Telemetry'!$J$6:$J$559,'Game Telemetry'!$C$6:$C$559,$B14) -> 55.365
B15: 2 | C15: =AVERAGEIFS('Game Telemetry'!$J$6:$J$559,'Game Telemetry'!$C$6:$C$559,$B15,'Game Telemetry'!$Q$6:$Q$559,"25–44") -> 62.263158 | D15: =AVERAGEIFS('Game Telemetry'!$J$6:$J$559,'Game Telemetry'!$C$6:$C$559,$B15,'Game Telemetry'!$Q$6:$Q$559,"45–64") -> 55.805128 | E15: =AVERAGEIFS('Game Telemetry'!$J$6:$J$559,'Game Telemetry'!$C$6:$C$559,$B15,'Game Telemetry'!$Q$6:$Q$559,"65–80") -> 54.611765 | F15: =AVERAGEIFS('Game Telemetry'!$J$6:$J$559,'Game Telemetry'!$C$6:$C$559,$B15) -> 57.65045
B16: 3 | C16: =AVERAGEIFS('Game Telemetry'!$J$6:$J$559,'Game Telemetry'!$C$6:$C$559,$B16,'Game Telemetry'!$Q$6:$Q$559,"25–44") -> 61.489474 | D16: =AVERAGEIFS('Game Telemetry'!$J$6:$J$559,'Game Telemetry'!$C$6:$C$559,$B16,'Game Telemetry'!$Q$6:$Q$559,"45–64") -> 60.421622 | E16: =AVERAGEIFS('Game Telemetry'!$J$6:$J$559,'Game Telemetry'!$C$6:$C$559,$B16,'Game Telemetry'!$Q$6:$Q$559,"65–80") -> 55.306897 | F16: =AVERAGEIFS('Game Telemetry'!$J$6:$J$559,'Game Telemetry'!$C$6:$C$559,$B16) -> 59.385577
B17: 4 | C17: =AVERAGEIFS('Game Telemetry'!$J$6:$J$559,'Game Telemetry'!$C$6:$C$559,$B17,'Game Telemetry'!$Q$6:$Q$559,"25–44") -> 60.407895 | D17: =AVERAGEIFS('Game Telemetry'!$J$6:$J$559,'Game Telemetry'!$C$6:$C$559,$B17,'Game Telemetry'!$Q$6:$Q$559,"45–64") -> 58.594444 | E17: =AVERAGEIFS('Game Telemetry'!$J$6:$J$559,'Game Telemetry'!$C$6:$C$559,$B17,'Game Telemetry'!$Q$6:$Q$559,"65–80") -> 52.196 | F17: =AVERAGEIFS('Game Telemetry'!$J$6:$J$559,'Game Telemetry'!$C$6:$C$559,$B17) -> 57.674747
B18: 5 | C18: =AVERAGEIFS('Game Telemetry'!$J$6:$J$559,'Game Telemetry'!$C$6:$C$559,$B18,'Game Telemetry'!$Q$6:$Q$559,"25–44") -> 63.894737 | D18: =AVERAGEIFS('Game Telemetry'!$J$6:$J$559,'Game Telemetry'!$C$6:$C$559,$B18,'Game Telemetry'!$Q$6:$Q$559,"45–64") -> 62.226471 | E18: =AVERAGEIFS('Game Telemetry'!$J$6:$J$559,'Game Telemetry'!$C$6:$C$559,$B18,'Game Telemetry'!$Q$6:$Q$559,"65–80") -> 58.472 | F18: =AVERAGEIFS('Game Telemetry'!$J$6:$J$559,'Game Telemetry'!$C$6:$C$559,$B18) -> 61.912371
B19: Mean obstacles hit (n)
B20: Session | C20: 25–44 | D20: 45–64 | E20: 65–80 | F20: All bands
B21: 1 | C21: =AVERAGEIFS('Game Telemetry'!$H$6:$H$559,'Game Telemetry'!$C$6:$C$559,$B21,'Game Telemetry'!$Q$6:$Q$559,"25–44") -> 1.3947368 | D21: =AVERAGEIFS('Game Telemetry'!$H$6:$H$559,'Game Telemetry'!$C$6:$C$559,$B21,'Game Telemetry'!$Q$6:$Q$559,"45–64") -> 1.5365854 | E21: =AVERAGEIFS('Game Telemetry'!$H$6:$H$559,'Game Telemetry'!$C$6:$C$559,$B21,'Game Telemetry'!$Q$6:$Q$559,"65–80") -> 2.3414634 | F21: =AVERAGEIFS('Game Telemetry'!$H$6:$H$559,'Game Telemetry'!$C$6:$C$559,$B21) -> 1.7666667
B22: 2 | C22: =AVERAGEIFS('Game Telemetry'!$H$6:$H$559,'Game Telemetry'!$C$6:$C$559,$B22,'Game Telemetry'!$Q$6:$Q$559,"25–44") -> 1.3684211 | D22: =AVERAGEIFS('Game Telemetry'!$H$6:$H$559,'Game Telemetry'!$C$6:$C$559,$B22,'Game Telemetry'!$Q$6:$Q$559,"45–64") -> 1.7692308 | E22: =AVERAGEIFS('Game Telemetry'!$H$6:$H$559,'Game Telemetry'!$C$6:$C$559,$B22,'Game Telemetry'!$Q$6:$Q$559,"65–80") -> 1.9705882 | F22: =AVERAGEIFS('Game Telemetry'!$H$6:$H$559,'Game Telemetry'!$C$6:$C$559,$B22) -> 1.6936937
B23: 3 | C23: =AVERAGEIFS('Game Telemetry'!$H$6:$H$559,'Game Telemetry'!$C$6:$C$559,$B23,'Game Telemetry'!$Q$6:$Q$559,"25–44") -> 1.0789474 | D23: =AVERAGEIFS('Game Telemetry'!$H$6:$H$559,'Game Telemetry'!$C$6:$C$559,$B23,'Game Telemetry'!$Q$6:$Q$559,"45–64") -> 1.5135135 | E23: =AVERAGEIFS('Game Telemetry'!$H$6:$H$559,'Game Telemetry'!$C$6:$C$559,$B23,'Game Telemetry'!$Q$6:$Q$559,"65–80") -> 2.1034483 | F23: =AVERAGEIFS('Game Telemetry'!$H$6:$H$559,'Game Telemetry'!$C$6:$C$559,$B23) -> 1.5192308
B24: 4 | C24: =AVERAGEIFS('Game Telemetry'!$H$6:$H$559,'Game Telemetry'!$C$6:$C$559,$B24,'Game Telemetry'!$Q$6:$Q$559,"25–44") -> 1.5526316 | D24: =AVERAGEIFS('Game Telemetry'!$H$6:$H$559,'Game Telemetry'!$C$6:$C$559,$B24,'Game Telemetry'!$Q$6:$Q$559,"45–64") -> 1.4444444 | E24: =AVERAGEIFS('Game Telemetry'!$H$6:$H$559,'Game Telemetry'!$C$6:$C$559,$B24,'Game Telemetry'!$Q$6:$Q$559,"65–80") -> 1.92 | F24: =AVERAGEIFS('Game Telemetry'!$H$6:$H$559,'Game Telemetry'!$C$6:$C$559,$B24) -> 1.6060606
B25: 5 | C25: =AVERAGEIFS('Game Telemetry'!$H$6:$H$559,'Game Telemetry'!$C$6:$C$559,$B25,'Game Telemetry'!$Q$6:$Q$559,"25–44") -> 1.2105263 | D25: =AVERAGEIFS('Game Telemetry'!$H$6:$H$559,'Game Telemetry'!$C$6:$C$559,$B25,'Game Telemetry'!$Q$6:$Q$559,"45–64") -> 1.7058824 | E25: =AVERAGEIFS('Game Telemetry'!$H$6:$H$559,'Game Telemetry'!$C$6:$C$559,$B25,'Game Telemetry'!$Q$6:$Q$559,"65–80") -> 1.56 | F25: =AVERAGEIFS('Game Telemetry'!$H$6:$H$559,'Game Telemetry'!$C$6:$C$559,$B25) -> 1.4742268
B26: Mean difficulty multiplier at run end (×)
B27: Session | C27: 25–44 | D27: 45–64 | E27: 65–80 | F27: All bands
B28: 1 | C28: =AVERAGEIFS('Game Telemetry'!$L$6:$L$559,'Game Telemetry'!$C$6:$C$559,$B28,'Game Telemetry'!$Q$6:$Q$559,"25–44") -> 0.62105263 | D28: =AVERAGEIFS('Game Telemetry'!$L$6:$L$559,'Game Telemetry'!$C$6:$C$559,$B28,'Game Telemetry'!$Q$6:$Q$559,"45–64") -> 0.60365854 | E28: =AVERAGEIFS('Game Telemetry'!$L$6:$L$559,'Game Telemetry'!$C$6:$C$559,$B28,'Game Telemetry'!$Q$6:$Q$559,"65–80") -> 0.55243902 | F28: =AVERAGEIFS('Game Telemetry'!$L$6:$L$559,'Game Telemetry'!$C$6:$C$559,$B28) -> 0.59166667
B29: 2 | C29: =AVERAGEIFS('Game Telemetry'!$L$6:$L$559,'Game Telemetry'!$C$6:$C$559,$B29,'Game Telemetry'!$Q$6:$Q$559,"25–44") -> 0.625 | D29: =AVERAGEIFS('Game Telemetry'!$L$6:$L$559,'Game Telemetry'!$C$6:$C$559,$B29,'Game Telemetry'!$Q$6:$Q$559,"45–64") -> 0.60128205 | E29: =AVERAGEIFS('Game Telemetry'!$L$6:$L$559,'Game Telemetry'!$C$6:$C$559,$B29,'Game Telemetry'!$Q$6:$Q$559,"65–80") -> 0.575 | F29: =AVERAGEIFS('Game Telemetry'!$L$6:$L$559,'Game Telemetry'!$C$6:$C$559,$B29) -> 0.60135135
B30: 3 | C30: =AVERAGEIFS('Game Telemetry'!$L$6:$L$559,'Game Telemetry'!$C$6:$C$559,$B30,'Game Telemetry'!$Q$6:$Q$559,"25–44") -> 0.65 | D30: =AVERAGEIFS('Game Telemetry'!$L$6:$L$559,'Game Telemetry'!$C$6:$C$559,$B30,'Game Telemetry'!$Q$6:$Q$559,"45–64") -> 0.61891892 | E30: =AVERAGEIFS('Game Telemetry'!$L$6:$L$559,'Game Telemetry'!$C$6:$C$559,$B30,'Game Telemetry'!$Q$6:$Q$559,"65–80") -> 0.6 | F30: =AVERAGEIFS('Game Telemetry'!$L$6:$L$559,'Game Telemetry'!$C$6:$C$559,$B30) -> 0.625
B31: 4 | C31: =AVERAGEIFS('Game Telemetry'!$L$6:$L$559,'Game Telemetry'!$C$6:$C$559,$B31,'Game Telemetry'!$Q$6:$Q$559,"25–44") -> 0.60921053 | D31: =AVERAGEIFS('Game Telemetry'!$L$6:$L$559,'Game Telemetry'!$C$6:$C$559,$B31,'Game Telemetry'!$Q$6:$Q$559,"45–64") -> 0.6125 | E31: =AVERAGEIFS('Game Telemetry'!$L$6:$L$559,'Game Telemetry'!$C$6:$C$559,$B31,'Game Telemetry'!$Q$6:$Q$559,"65–80") -> 0.586 | F31: =AVERAGEIFS('Game Telemetry'!$L$6:$L$559,'Game Telemetry'!$C$6:$C$559,$B31) -> 0.60454545
B32: 5 | C32: =AVERAGEIFS('Game Telemetry'!$L$6:$L$559,'Game Telemetry'!$C$6:$C$559,$B32,'Game Telemetry'!$Q$6:$Q$559,"25–44") -> 0.62368421 | D32: =AVERAGEIFS('Game Telemetry'!$L$6:$L$559,'Game Telemetry'!$C$6:$C$559,$B32,'Game Telemetry'!$Q$6:$Q$559,"45–64") -> 0.61029412 | E32: =AVERAGEIFS('Game Telemetry'!$L$6:$L$559,'Game Telemetry'!$C$6:$C$559,$B32,'Game Telemetry'!$Q$6:$Q$559,"65–80") -> 0.614 | F32: =AVERAGEIFS('Game Telemetry'!$L$6:$L$559,'Game Telemetry'!$C$6:$C$559,$B32) -> 0.61649485
B33: Sessions 5–7 at a glance (session 5 = 97 protocol completers; sessions 6–7 = 15 returnees)
B34: Session | C34: Runs | D34: Mean score (points) | E34: Mean balance (%)
B35: 5 | C35: =COUNTIF('Game Telemetry'!$C$6:$C$559,5) -> 97 | D35: =AVERAGEIFS('Game Telemetry'!$N$6:$N$559,'Game Telemetry'!$C$6:$C$559,5) -> 331.27835 | E35: =AVERAGEIFS('Game Telemetry'!$J$6:$J$559,'Game Telemetry'!$C$6:$C$559,5) -> 61.912371
B36: 6 | C36: =COUNTIF('Game Telemetry'!$C$6:$C$559,6) -> 15 | D36: =AVERAGEIFS('Game Telemetry'!$N$6:$N$559,'Game Telemetry'!$C$6:$C$559,6) -> 328.13333 | E36: =AVERAGEIFS('Game Telemetry'!$J$6:$J$559,'Game Telemetry'!$C$6:$C$559,6) -> 55.746667
B37: 7 | C37: =COUNTIF('Game Telemetry'!$C$6:$C$559,7) -> 8 | D37: =AVERAGEIFS('Game Telemetry'!$N$6:$N$559,'Game Telemetry'!$C$6:$C$559,7) -> 336.5 | E37: =AVERAGEIFS('Game Telemetry'!$J$6:$J$559,'Game Telemetry'!$C$6:$C$559,7) -> 51.7625
B38: Note: sessions 6–7 exist only for the 15 voluntary returnees; session 5 row includes all 97 protocol completers.
B40: Overall
B41: Total runs | C41: =COUNTA('Game Telemetry'!$B$6:$B$559) -> 554
B42: Mean score (all runs) | C42: =AVERAGE('Game Telemetry'!$N$6:$N$559) -> 326.50361
B43: Mean balance (all runs) | C43: =AVERAGE('Game Telemetry'!$J$6:$J$559) -> 58.095126
...
